2024-04-15 01:12:20,615 - ERROR - An error occurred: An error occurred while making double line graph: Could not interpret value `inv_total` for `x`. An entry with this name does not appear in `data`.
Traceback (most recent call last):
  File "C:\Users\24dan\Documents\AccountingCapstone\DFA\src\main\python\scripts\generate_graphs.py", line 168, in make_double_line
    sns.lineplot(x=x_name, y=y_name, data=df, label=y_name)
  File "C:\Users\24dan\AppData\Local\Packages\PythonSoftwareFoundation.Python.3.11_qbz5n2kfra8p0\LocalCache\local-packages\Python311\site-packages\seaborn\relational.py", line 485, in lineplot
    p = _LinePlotter(
        ^^^^^^^^^^^^^
  File "C:\Users\24dan\AppData\Local\Packages\PythonSoftwareFoundation.Python.3.11_qbz5n2kfra8p0\LocalCache\local-packages\Python311\site-packages\seaborn\relational.py", line 216, in __init__
    super().__init__(data=data, variables=variables)
  File "C:\Users\24dan\AppData\Local\Packages\PythonSoftwareFoundation.Python.3.11_qbz5n2kfra8p0\LocalCache\local-packages\Python311\site-packages\seaborn\_base.py", line 634, in __init__
    self.assign_variables(data, variables)
  File "C:\Users\24dan\AppData\Local\Packages\PythonSoftwareFoundation.Python.3.11_qbz5n2kfra8p0\LocalCache\local-packages\Python311\site-packages\seaborn\_base.py", line 679, in assign_variables
    plot_data = PlotData(data, variables)
                ^^^^^^^^^^^^^^^^^^^^^^^^^
  File "C:\Users\24dan\AppData\Local\Packages\PythonSoftwareFoundation.Python.3.11_qbz5n2kfra8p0\LocalCache\local-packages\Python311\site-packages\seaborn\_core\data.py", line 58, in __init__
    frame, names, ids = self._assign_variables(data, variables)
                        ^^^^^^^^^^^^^^^^^^^^^^^^^^^^^^^^^^^^^^^
  File "C:\Users\24dan\AppData\Local\Packages\PythonSoftwareFoundation.Python.3.11_qbz5n2kfra8p0\LocalCache\local-packages\Python311\site-packages\seaborn\_core\data.py", line 232, in _assign_variables
    raise ValueError(err)
ValueError: Could not interpret value `inv_total` for `x`. An entry with this name does not appear in `data`.

During handling of the above exception, another exception occurred:

Traceback (most recent call last):
  File "C:\Users\24dan\Documents\AccountingCapstone\DFA\src\main\python\scripts\generate_graphs.py", line 233, in <module>
    make_double_line(getDataFrame(str(sql_statement)), str(graph_name), 7, 14, graph_x_name, graph_y_name, graph_y2_name)
  File "C:\Users\24dan\Documents\AccountingCapstone\DFA\src\main\python\scripts\generate_graphs.py", line 176, in make_double_line
    raise RuntimeError("An error occurred while making double line graph: %s" % e)
RuntimeError: An error occurred while making double line graph: Could not interpret value `inv_total` for `x`. An entry with this name does not appear in `data`.
2024-04-15 01:59:20,273 - ERROR - An error occurred: An error occurred while making double line graph: Could not interpret value `Month` for `x`. An entry with this name does not appear in `data`.
Traceback (most recent call last):
  File "C:\Users\24dan\Documents\AccountingCapstone\DFA\src\main\python\scripts\generate_graphs.py", line 168, in make_double_line
    sns.lineplot(x=x_name, y=y_name, data=df, label=y_name)
  File "C:\Users\24dan\AppData\Local\Packages\PythonSoftwareFoundation.Python.3.11_qbz5n2kfra8p0\LocalCache\local-packages\Python311\site-packages\seaborn\relational.py", line 485, in lineplot
    p = _LinePlotter(
        ^^^^^^^^^^^^^
  File "C:\Users\24dan\AppData\Local\Packages\PythonSoftwareFoundation.Python.3.11_qbz5n2kfra8p0\LocalCache\local-packages\Python311\site-packages\seaborn\relational.py", line 216, in __init__
    super().__init__(data=data, variables=variables)
  File "C:\Users\24dan\AppData\Local\Packages\PythonSoftwareFoundation.Python.3.11_qbz5n2kfra8p0\LocalCache\local-packages\Python311\site-packages\seaborn\_base.py", line 634, in __init__
    self.assign_variables(data, variables)
  File "C:\Users\24dan\AppData\Local\Packages\PythonSoftwareFoundation.Python.3.11_qbz5n2kfra8p0\LocalCache\local-packages\Python311\site-packages\seaborn\_base.py", line 679, in assign_variables
    plot_data = PlotData(data, variables)
                ^^^^^^^^^^^^^^^^^^^^^^^^^
  File "C:\Users\24dan\AppData\Local\Packages\PythonSoftwareFoundation.Python.3.11_qbz5n2kfra8p0\LocalCache\local-packages\Python311\site-packages\seaborn\_core\data.py", line 58, in __init__
    frame, names, ids = self._assign_variables(data, variables)
                        ^^^^^^^^^^^^^^^^^^^^^^^^^^^^^^^^^^^^^^^
  File "C:\Users\24dan\AppData\Local\Packages\PythonSoftwareFoundation.Python.3.11_qbz5n2kfra8p0\LocalCache\local-packages\Python311\site-packages\seaborn\_core\data.py", line 232, in _assign_variables
    raise ValueError(err)
ValueError: Could not interpret value `Month` for `x`. An entry with this name does not appear in `data`.

During handling of the above exception, another exception occurred:

Traceback (most recent call last):
  File "C:\Users\24dan\Documents\AccountingCapstone\DFA\src\main\python\scripts\generate_graphs.py", line 233, in <module>
    make_double_line(getDataFrame(str(sql_statement)), str(graph_name), 7, 14, graph_x_name, graph_y_name, graph_y2_name)
  File "C:\Users\24dan\Documents\AccountingCapstone\DFA\src\main\python\scripts\generate_graphs.py", line 176, in make_double_line
    raise RuntimeError("An error occurred while making double line graph: %s" % e)
RuntimeError: An error occurred while making double line graph: Could not interpret value `Month` for `x`. An entry with this name does not appear in `data`.
2024-04-15 01:59:45,790 - ERROR - An error occurred: An error occurred while making double line graph: Could not interpret value `Month` for `x`. An entry with this name does not appear in `data`.
Traceback (most recent call last):
  File "C:\Users\24dan\Documents\AccountingCapstone\DFA\src\main\python\scripts\generate_graphs.py", line 168, in make_double_line
    sns.lineplot(x=x_name, y=y_name, data=df, label=y_name)
  File "C:\Users\24dan\AppData\Local\Packages\PythonSoftwareFoundation.Python.3.11_qbz5n2kfra8p0\LocalCache\local-packages\Python311\site-packages\seaborn\relational.py", line 485, in lineplot
    p = _LinePlotter(
        ^^^^^^^^^^^^^
  File "C:\Users\24dan\AppData\Local\Packages\PythonSoftwareFoundation.Python.3.11_qbz5n2kfra8p0\LocalCache\local-packages\Python311\site-packages\seaborn\relational.py", line 216, in __init__
    super().__init__(data=data, variables=variables)
  File "C:\Users\24dan\AppData\Local\Packages\PythonSoftwareFoundation.Python.3.11_qbz5n2kfra8p0\LocalCache\local-packages\Python311\site-packages\seaborn\_base.py", line 634, in __init__
    self.assign_variables(data, variables)
  File "C:\Users\24dan\AppData\Local\Packages\PythonSoftwareFoundation.Python.3.11_qbz5n2kfra8p0\LocalCache\local-packages\Python311\site-packages\seaborn\_base.py", line 679, in assign_variables
    plot_data = PlotData(data, variables)
                ^^^^^^^^^^^^^^^^^^^^^^^^^
  File "C:\Users\24dan\AppData\Local\Packages\PythonSoftwareFoundation.Python.3.11_qbz5n2kfra8p0\LocalCache\local-packages\Python311\site-packages\seaborn\_core\data.py", line 58, in __init__
    frame, names, ids = self._assign_variables(data, variables)
                        ^^^^^^^^^^^^^^^^^^^^^^^^^^^^^^^^^^^^^^^
  File "C:\Users\24dan\AppData\Local\Packages\PythonSoftwareFoundation.Python.3.11_qbz5n2kfra8p0\LocalCache\local-packages\Python311\site-packages\seaborn\_core\data.py", line 232, in _assign_variables
    raise ValueError(err)
ValueError: Could not interpret value `Month` for `x`. An entry with this name does not appear in `data`.

During handling of the above exception, another exception occurred:

Traceback (most recent call last):
  File "C:\Users\24dan\Documents\AccountingCapstone\DFA\src\main\python\scripts\generate_graphs.py", line 233, in <module>
    make_double_line(getDataFrame(str(sql_statement)), str(graph_name), 7, 14, graph_x_name, graph_y_name, graph_y2_name)
  File "C:\Users\24dan\Documents\AccountingCapstone\DFA\src\main\python\scripts\generate_graphs.py", line 176, in make_double_line
    raise RuntimeError("An error occurred while making double line graph: %s" % e)
RuntimeError: An error occurred while making double line graph: Could not interpret value `Month` for `x`. An entry with this name does not appear in `data`.
2024-04-15 02:00:11,396 - ERROR - An error occurred: An error occurred while making double line graph: Could not interpret value `Month` for `x`. An entry with this name does not appear in `data`.
Traceback (most recent call last):
  File "C:\Users\24dan\Documents\AccountingCapstone\DFA\src\main\python\scripts\generate_graphs.py", line 168, in make_double_line
    sns.lineplot(x=x_name, y=y_name, data=df, label=y_name)
  File "C:\Users\24dan\AppData\Local\Packages\PythonSoftwareFoundation.Python.3.11_qbz5n2kfra8p0\LocalCache\local-packages\Python311\site-packages\seaborn\relational.py", line 485, in lineplot
    p = _LinePlotter(
        ^^^^^^^^^^^^^
  File "C:\Users\24dan\AppData\Local\Packages\PythonSoftwareFoundation.Python.3.11_qbz5n2kfra8p0\LocalCache\local-packages\Python311\site-packages\seaborn\relational.py", line 216, in __init__
    super().__init__(data=data, variables=variables)
  File "C:\Users\24dan\AppData\Local\Packages\PythonSoftwareFoundation.Python.3.11_qbz5n2kfra8p0\LocalCache\local-packages\Python311\site-packages\seaborn\_base.py", line 634, in __init__
    self.assign_variables(data, variables)
  File "C:\Users\24dan\AppData\Local\Packages\PythonSoftwareFoundation.Python.3.11_qbz5n2kfra8p0\LocalCache\local-packages\Python311\site-packages\seaborn\_base.py", line 679, in assign_variables
    plot_data = PlotData(data, variables)
                ^^^^^^^^^^^^^^^^^^^^^^^^^
  File "C:\Users\24dan\AppData\Local\Packages\PythonSoftwareFoundation.Python.3.11_qbz5n2kfra8p0\LocalCache\local-packages\Python311\site-packages\seaborn\_core\data.py", line 58, in __init__
    frame, names, ids = self._assign_variables(data, variables)
                        ^^^^^^^^^^^^^^^^^^^^^^^^^^^^^^^^^^^^^^^
  File "C:\Users\24dan\AppData\Local\Packages\PythonSoftwareFoundation.Python.3.11_qbz5n2kfra8p0\LocalCache\local-packages\Python311\site-packages\seaborn\_core\data.py", line 232, in _assign_variables
    raise ValueError(err)
ValueError: Could not interpret value `Month` for `x`. An entry with this name does not appear in `data`.

During handling of the above exception, another exception occurred:

Traceback (most recent call last):
  File "C:\Users\24dan\Documents\AccountingCapstone\DFA\src\main\python\scripts\generate_graphs.py", line 233, in <module>
    make_double_line(getDataFrame(str(sql_statement)), str(graph_name), 7, 14, graph_x_name, graph_y_name, graph_y2_name)
  File "C:\Users\24dan\Documents\AccountingCapstone\DFA\src\main\python\scripts\generate_graphs.py", line 176, in make_double_line
    raise RuntimeError("An error occurred while making double line graph: %s" % e)
RuntimeError: An error occurred while making double line graph: Could not interpret value `Month` for `x`. An entry with this name does not appear in `data`.
2024-04-15 02:01:12,488 - ERROR - An error occurred: An error occurred while making double line graph: Could not interpret value `Month` for `x`. An entry with this name does not appear in `data`.
Traceback (most recent call last):
  File "C:\Users\24dan\Documents\AccountingCapstone\DFA\src\main\python\scripts\generate_graphs.py", line 168, in make_double_line
    sns.lineplot(x=x_name, y=y_name, data=df, label=y_name)
  File "C:\Users\24dan\AppData\Local\Packages\PythonSoftwareFoundation.Python.3.11_qbz5n2kfra8p0\LocalCache\local-packages\Python311\site-packages\seaborn\relational.py", line 485, in lineplot
    p = _LinePlotter(
        ^^^^^^^^^^^^^
  File "C:\Users\24dan\AppData\Local\Packages\PythonSoftwareFoundation.Python.3.11_qbz5n2kfra8p0\LocalCache\local-packages\Python311\site-packages\seaborn\relational.py", line 216, in __init__
    super().__init__(data=data, variables=variables)
  File "C:\Users\24dan\AppData\Local\Packages\PythonSoftwareFoundation.Python.3.11_qbz5n2kfra8p0\LocalCache\local-packages\Python311\site-packages\seaborn\_base.py", line 634, in __init__
    self.assign_variables(data, variables)
  File "C:\Users\24dan\AppData\Local\Packages\PythonSoftwareFoundation.Python.3.11_qbz5n2kfra8p0\LocalCache\local-packages\Python311\site-packages\seaborn\_base.py", line 679, in assign_variables
    plot_data = PlotData(data, variables)
                ^^^^^^^^^^^^^^^^^^^^^^^^^
  File "C:\Users\24dan\AppData\Local\Packages\PythonSoftwareFoundation.Python.3.11_qbz5n2kfra8p0\LocalCache\local-packages\Python311\site-packages\seaborn\_core\data.py", line 58, in __init__
    frame, names, ids = self._assign_variables(data, variables)
                        ^^^^^^^^^^^^^^^^^^^^^^^^^^^^^^^^^^^^^^^
  File "C:\Users\24dan\AppData\Local\Packages\PythonSoftwareFoundation.Python.3.11_qbz5n2kfra8p0\LocalCache\local-packages\Python311\site-packages\seaborn\_core\data.py", line 232, in _assign_variables
    raise ValueError(err)
ValueError: Could not interpret value `Month` for `x`. An entry with this name does not appear in `data`.

During handling of the above exception, another exception occurred:

Traceback (most recent call last):
  File "C:\Users\24dan\Documents\AccountingCapstone\DFA\src\main\python\scripts\generate_graphs.py", line 233, in <module>
    make_double_line(getDataFrame(str(sql_statement)), str(graph_name), 7, 14, graph_x_name, graph_y_name, graph_y2_name)
  File "C:\Users\24dan\Documents\AccountingCapstone\DFA\src\main\python\scripts\generate_graphs.py", line 176, in make_double_line
    raise RuntimeError("An error occurred while making double line graph: %s" % e)
RuntimeError: An error occurred while making double line graph: Could not interpret value `Month` for `x`. An entry with this name does not appear in `data`.
2024-04-15 02:01:29,802 - ERROR - An error occurred: An error occurred while making double line graph: Could not interpret value `Month` for `x`. An entry with this name does not appear in `data`.
Traceback (most recent call last):
  File "C:\Users\24dan\Documents\AccountingCapstone\DFA\src\main\python\scripts\generate_graphs.py", line 168, in make_double_line
    sns.lineplot(x=x_name, y=y_name, data=df, label=y_name)
  File "C:\Users\24dan\AppData\Local\Packages\PythonSoftwareFoundation.Python.3.11_qbz5n2kfra8p0\LocalCache\local-packages\Python311\site-packages\seaborn\relational.py", line 485, in lineplot
    p = _LinePlotter(
        ^^^^^^^^^^^^^
  File "C:\Users\24dan\AppData\Local\Packages\PythonSoftwareFoundation.Python.3.11_qbz5n2kfra8p0\LocalCache\local-packages\Python311\site-packages\seaborn\relational.py", line 216, in __init__
    super().__init__(data=data, variables=variables)
  File "C:\Users\24dan\AppData\Local\Packages\PythonSoftwareFoundation.Python.3.11_qbz5n2kfra8p0\LocalCache\local-packages\Python311\site-packages\seaborn\_base.py", line 634, in __init__
    self.assign_variables(data, variables)
  File "C:\Users\24dan\AppData\Local\Packages\PythonSoftwareFoundation.Python.3.11_qbz5n2kfra8p0\LocalCache\local-packages\Python311\site-packages\seaborn\_base.py", line 679, in assign_variables
    plot_data = PlotData(data, variables)
                ^^^^^^^^^^^^^^^^^^^^^^^^^
  File "C:\Users\24dan\AppData\Local\Packages\PythonSoftwareFoundation.Python.3.11_qbz5n2kfra8p0\LocalCache\local-packages\Python311\site-packages\seaborn\_core\data.py", line 58, in __init__
    frame, names, ids = self._assign_variables(data, variables)
                        ^^^^^^^^^^^^^^^^^^^^^^^^^^^^^^^^^^^^^^^
  File "C:\Users\24dan\AppData\Local\Packages\PythonSoftwareFoundation.Python.3.11_qbz5n2kfra8p0\LocalCache\local-packages\Python311\site-packages\seaborn\_core\data.py", line 232, in _assign_variables
    raise ValueError(err)
ValueError: Could not interpret value `Month` for `x`. An entry with this name does not appear in `data`.

During handling of the above exception, another exception occurred:

Traceback (most recent call last):
  File "C:\Users\24dan\Documents\AccountingCapstone\DFA\src\main\python\scripts\generate_graphs.py", line 233, in <module>
    make_double_line(getDataFrame(str(sql_statement)), str(graph_name), 7, 14, graph_x_name, graph_y_name, graph_y2_name)
  File "C:\Users\24dan\Documents\AccountingCapstone\DFA\src\main\python\scripts\generate_graphs.py", line 176, in make_double_line
    raise RuntimeError("An error occurred while making double line graph: %s" % e)
RuntimeError: An error occurred while making double line graph: Could not interpret value `Month` for `x`. An entry with this name does not appear in `data`.
2024-04-15 02:01:35,984 - ERROR - An error occurred: An error occurred while making double line graph: Could not interpret value `Month` for `x`. An entry with this name does not appear in `data`.
Traceback (most recent call last):
  File "C:\Users\24dan\Documents\AccountingCapstone\DFA\src\main\python\scripts\generate_graphs.py", line 168, in make_double_line
    sns.lineplot(x=x_name, y=y_name, data=df, label=y_name)
  File "C:\Users\24dan\AppData\Local\Packages\PythonSoftwareFoundation.Python.3.11_qbz5n2kfra8p0\LocalCache\local-packages\Python311\site-packages\seaborn\relational.py", line 485, in lineplot
    p = _LinePlotter(
        ^^^^^^^^^^^^^
  File "C:\Users\24dan\AppData\Local\Packages\PythonSoftwareFoundation.Python.3.11_qbz5n2kfra8p0\LocalCache\local-packages\Python311\site-packages\seaborn\relational.py", line 216, in __init__
    super().__init__(data=data, variables=variables)
  File "C:\Users\24dan\AppData\Local\Packages\PythonSoftwareFoundation.Python.3.11_qbz5n2kfra8p0\LocalCache\local-packages\Python311\site-packages\seaborn\_base.py", line 634, in __init__
    self.assign_variables(data, variables)
  File "C:\Users\24dan\AppData\Local\Packages\PythonSoftwareFoundation.Python.3.11_qbz5n2kfra8p0\LocalCache\local-packages\Python311\site-packages\seaborn\_base.py", line 679, in assign_variables
    plot_data = PlotData(data, variables)
                ^^^^^^^^^^^^^^^^^^^^^^^^^
  File "C:\Users\24dan\AppData\Local\Packages\PythonSoftwareFoundation.Python.3.11_qbz5n2kfra8p0\LocalCache\local-packages\Python311\site-packages\seaborn\_core\data.py", line 58, in __init__
    frame, names, ids = self._assign_variables(data, variables)
                        ^^^^^^^^^^^^^^^^^^^^^^^^^^^^^^^^^^^^^^^
  File "C:\Users\24dan\AppData\Local\Packages\PythonSoftwareFoundation.Python.3.11_qbz5n2kfra8p0\LocalCache\local-packages\Python311\site-packages\seaborn\_core\data.py", line 232, in _assign_variables
    raise ValueError(err)
ValueError: Could not interpret value `Month` for `x`. An entry with this name does not appear in `data`.

During handling of the above exception, another exception occurred:

Traceback (most recent call last):
  File "C:\Users\24dan\Documents\AccountingCapstone\DFA\src\main\python\scripts\generate_graphs.py", line 233, in <module>
    make_double_line(getDataFrame(str(sql_statement)), str(graph_name), 7, 14, graph_x_name, graph_y_name, graph_y2_name)
  File "C:\Users\24dan\Documents\AccountingCapstone\DFA\src\main\python\scripts\generate_graphs.py", line 176, in make_double_line
    raise RuntimeError("An error occurred while making double line graph: %s" % e)
RuntimeError: An error occurred while making double line graph: Could not interpret value `Month` for `x`. An entry with this name does not appear in `data`.
2024-04-15 02:01:47,069 - ERROR - An error occurred: An error occurred while making double line graph: Could not interpret value `Month` for `x`. An entry with this name does not appear in `data`.
Traceback (most recent call last):
  File "C:\Users\24dan\Documents\AccountingCapstone\DFA\src\main\python\scripts\generate_graphs.py", line 168, in make_double_line
    sns.lineplot(x=x_name, y=y_name, data=df, label=y_name)
  File "C:\Users\24dan\AppData\Local\Packages\PythonSoftwareFoundation.Python.3.11_qbz5n2kfra8p0\LocalCache\local-packages\Python311\site-packages\seaborn\relational.py", line 485, in lineplot
    p = _LinePlotter(
        ^^^^^^^^^^^^^
  File "C:\Users\24dan\AppData\Local\Packages\PythonSoftwareFoundation.Python.3.11_qbz5n2kfra8p0\LocalCache\local-packages\Python311\site-packages\seaborn\relational.py", line 216, in __init__
    super().__init__(data=data, variables=variables)
  File "C:\Users\24dan\AppData\Local\Packages\PythonSoftwareFoundation.Python.3.11_qbz5n2kfra8p0\LocalCache\local-packages\Python311\site-packages\seaborn\_base.py", line 634, in __init__
    self.assign_variables(data, variables)
  File "C:\Users\24dan\AppData\Local\Packages\PythonSoftwareFoundation.Python.3.11_qbz5n2kfra8p0\LocalCache\local-packages\Python311\site-packages\seaborn\_base.py", line 679, in assign_variables
    plot_data = PlotData(data, variables)
                ^^^^^^^^^^^^^^^^^^^^^^^^^
  File "C:\Users\24dan\AppData\Local\Packages\PythonSoftwareFoundation.Python.3.11_qbz5n2kfra8p0\LocalCache\local-packages\Python311\site-packages\seaborn\_core\data.py", line 58, in __init__
    frame, names, ids = self._assign_variables(data, variables)
                        ^^^^^^^^^^^^^^^^^^^^^^^^^^^^^^^^^^^^^^^
  File "C:\Users\24dan\AppData\Local\Packages\PythonSoftwareFoundation.Python.3.11_qbz5n2kfra8p0\LocalCache\local-packages\Python311\site-packages\seaborn\_core\data.py", line 232, in _assign_variables
    raise ValueError(err)
ValueError: Could not interpret value `Month` for `x`. An entry with this name does not appear in `data`.

During handling of the above exception, another exception occurred:

Traceback (most recent call last):
  File "C:\Users\24dan\Documents\AccountingCapstone\DFA\src\main\python\scripts\generate_graphs.py", line 233, in <module>
    make_double_line(getDataFrame(str(sql_statement)), str(graph_name), 7, 14, graph_x_name, graph_y_name, graph_y2_name)
  File "C:\Users\24dan\Documents\AccountingCapstone\DFA\src\main\python\scripts\generate_graphs.py", line 176, in make_double_line
    raise RuntimeError("An error occurred while making double line graph: %s" % e)
RuntimeError: An error occurred while making double line graph: Could not interpret value `Month` for `x`. An entry with this name does not appear in `data`.
2024-04-15 02:03:31,442 - ERROR - An error occurred: An error occurred while making double line graph: Could not interpret value `Month` for `x`. An entry with this name does not appear in `data`.
Traceback (most recent call last):
  File "C:\Users\24dan\Documents\AccountingCapstone\DFA\src\main\python\scripts\generate_graphs.py", line 168, in make_double_line
    sns.lineplot(x=x_name, y=y_name, data=df, label=y_name)
  File "C:\Users\24dan\AppData\Local\Packages\PythonSoftwareFoundation.Python.3.11_qbz5n2kfra8p0\LocalCache\local-packages\Python311\site-packages\seaborn\relational.py", line 485, in lineplot
    p = _LinePlotter(
        ^^^^^^^^^^^^^
  File "C:\Users\24dan\AppData\Local\Packages\PythonSoftwareFoundation.Python.3.11_qbz5n2kfra8p0\LocalCache\local-packages\Python311\site-packages\seaborn\relational.py", line 216, in __init__
    super().__init__(data=data, variables=variables)
  File "C:\Users\24dan\AppData\Local\Packages\PythonSoftwareFoundation.Python.3.11_qbz5n2kfra8p0\LocalCache\local-packages\Python311\site-packages\seaborn\_base.py", line 634, in __init__
    self.assign_variables(data, variables)
  File "C:\Users\24dan\AppData\Local\Packages\PythonSoftwareFoundation.Python.3.11_qbz5n2kfra8p0\LocalCache\local-packages\Python311\site-packages\seaborn\_base.py", line 679, in assign_variables
    plot_data = PlotData(data, variables)
                ^^^^^^^^^^^^^^^^^^^^^^^^^
  File "C:\Users\24dan\AppData\Local\Packages\PythonSoftwareFoundation.Python.3.11_qbz5n2kfra8p0\LocalCache\local-packages\Python311\site-packages\seaborn\_core\data.py", line 58, in __init__
    frame, names, ids = self._assign_variables(data, variables)
                        ^^^^^^^^^^^^^^^^^^^^^^^^^^^^^^^^^^^^^^^
  File "C:\Users\24dan\AppData\Local\Packages\PythonSoftwareFoundation.Python.3.11_qbz5n2kfra8p0\LocalCache\local-packages\Python311\site-packages\seaborn\_core\data.py", line 232, in _assign_variables
    raise ValueError(err)
ValueError: Could not interpret value `Month` for `x`. An entry with this name does not appear in `data`.

During handling of the above exception, another exception occurred:

Traceback (most recent call last):
  File "C:\Users\24dan\Documents\AccountingCapstone\DFA\src\main\python\scripts\generate_graphs.py", line 233, in <module>
    make_double_line(getDataFrame(str(sql_statement)), str(graph_name), 7, 14, graph_x_name, graph_y_name, graph_y2_name)
  File "C:\Users\24dan\Documents\AccountingCapstone\DFA\src\main\python\scripts\generate_graphs.py", line 176, in make_double_line
    raise RuntimeError("An error occurred while making double line graph: %s" % e)
RuntimeError: An error occurred while making double line graph: Could not interpret value `Month` for `x`. An entry with this name does not appear in `data`.
2024-04-15 02:03:37,199 - ERROR - An error occurred: An error occurred while making double line graph: Could not interpret value `Month` for `x`. An entry with this name does not appear in `data`.
Traceback (most recent call last):
  File "C:\Users\24dan\Documents\AccountingCapstone\DFA\src\main\python\scripts\generate_graphs.py", line 168, in make_double_line
    sns.lineplot(x=x_name, y=y_name, data=df, label=y_name)
  File "C:\Users\24dan\AppData\Local\Packages\PythonSoftwareFoundation.Python.3.11_qbz5n2kfra8p0\LocalCache\local-packages\Python311\site-packages\seaborn\relational.py", line 485, in lineplot
    p = _LinePlotter(
        ^^^^^^^^^^^^^
  File "C:\Users\24dan\AppData\Local\Packages\PythonSoftwareFoundation.Python.3.11_qbz5n2kfra8p0\LocalCache\local-packages\Python311\site-packages\seaborn\relational.py", line 216, in __init__
    super().__init__(data=data, variables=variables)
  File "C:\Users\24dan\AppData\Local\Packages\PythonSoftwareFoundation.Python.3.11_qbz5n2kfra8p0\LocalCache\local-packages\Python311\site-packages\seaborn\_base.py", line 634, in __init__
    self.assign_variables(data, variables)
  File "C:\Users\24dan\AppData\Local\Packages\PythonSoftwareFoundation.Python.3.11_qbz5n2kfra8p0\LocalCache\local-packages\Python311\site-packages\seaborn\_base.py", line 679, in assign_variables
    plot_data = PlotData(data, variables)
                ^^^^^^^^^^^^^^^^^^^^^^^^^
  File "C:\Users\24dan\AppData\Local\Packages\PythonSoftwareFoundation.Python.3.11_qbz5n2kfra8p0\LocalCache\local-packages\Python311\site-packages\seaborn\_core\data.py", line 58, in __init__
    frame, names, ids = self._assign_variables(data, variables)
                        ^^^^^^^^^^^^^^^^^^^^^^^^^^^^^^^^^^^^^^^
  File "C:\Users\24dan\AppData\Local\Packages\PythonSoftwareFoundation.Python.3.11_qbz5n2kfra8p0\LocalCache\local-packages\Python311\site-packages\seaborn\_core\data.py", line 232, in _assign_variables
    raise ValueError(err)
ValueError: Could not interpret value `Month` for `x`. An entry with this name does not appear in `data`.

During handling of the above exception, another exception occurred:

Traceback (most recent call last):
  File "C:\Users\24dan\Documents\AccountingCapstone\DFA\src\main\python\scripts\generate_graphs.py", line 233, in <module>
    make_double_line(getDataFrame(str(sql_statement)), str(graph_name), 7, 14, graph_x_name, graph_y_name, graph_y2_name)
  File "C:\Users\24dan\Documents\AccountingCapstone\DFA\src\main\python\scripts\generate_graphs.py", line 176, in make_double_line
    raise RuntimeError("An error occurred while making double line graph: %s" % e)
RuntimeError: An error occurred while making double line graph: Could not interpret value `Month` for `x`. An entry with this name does not appear in `data`.
2024-04-15 02:05:05,180 - ERROR - An error occurred: An error occurred while making double line graph: Could not interpret value `Month` for `x`. An entry with this name does not appear in `data`.
Traceback (most recent call last):
  File "C:\Users\24dan\Documents\AccountingCapstone\DFA\src\main\python\scripts\generate_graphs.py", line 168, in make_double_line
    sns.lineplot(x=x_name, y=y_name, data=df, label=y_name)
  File "C:\Users\24dan\AppData\Local\Packages\PythonSoftwareFoundation.Python.3.11_qbz5n2kfra8p0\LocalCache\local-packages\Python311\site-packages\seaborn\relational.py", line 485, in lineplot
    p = _LinePlotter(
        ^^^^^^^^^^^^^
  File "C:\Users\24dan\AppData\Local\Packages\PythonSoftwareFoundation.Python.3.11_qbz5n2kfra8p0\LocalCache\local-packages\Python311\site-packages\seaborn\relational.py", line 216, in __init__
    super().__init__(data=data, variables=variables)
  File "C:\Users\24dan\AppData\Local\Packages\PythonSoftwareFoundation.Python.3.11_qbz5n2kfra8p0\LocalCache\local-packages\Python311\site-packages\seaborn\_base.py", line 634, in __init__
    self.assign_variables(data, variables)
  File "C:\Users\24dan\AppData\Local\Packages\PythonSoftwareFoundation.Python.3.11_qbz5n2kfra8p0\LocalCache\local-packages\Python311\site-packages\seaborn\_base.py", line 679, in assign_variables
    plot_data = PlotData(data, variables)
                ^^^^^^^^^^^^^^^^^^^^^^^^^
  File "C:\Users\24dan\AppData\Local\Packages\PythonSoftwareFoundation.Python.3.11_qbz5n2kfra8p0\LocalCache\local-packages\Python311\site-packages\seaborn\_core\data.py", line 58, in __init__
    frame, names, ids = self._assign_variables(data, variables)
                        ^^^^^^^^^^^^^^^^^^^^^^^^^^^^^^^^^^^^^^^
  File "C:\Users\24dan\AppData\Local\Packages\PythonSoftwareFoundation.Python.3.11_qbz5n2kfra8p0\LocalCache\local-packages\Python311\site-packages\seaborn\_core\data.py", line 232, in _assign_variables
    raise ValueError(err)
ValueError: Could not interpret value `Month` for `x`. An entry with this name does not appear in `data`.

During handling of the above exception, another exception occurred:

Traceback (most recent call last):
  File "C:\Users\24dan\Documents\AccountingCapstone\DFA\src\main\python\scripts\generate_graphs.py", line 233, in <module>
    make_double_line(getDataFrame(str(sql_statement)), str(graph_name), 7, 14, graph_x_name, graph_y_name, graph_y2_name)
  File "C:\Users\24dan\Documents\AccountingCapstone\DFA\src\main\python\scripts\generate_graphs.py", line 176, in make_double_line
    raise RuntimeError("An error occurred while making double line graph: %s" % e)
RuntimeError: An error occurred while making double line graph: Could not interpret value `Month` for `x`. An entry with this name does not appear in `data`.
2024-04-15 02:09:19,403 - ERROR - An error occurred: An error occurred while making double line graph: Could not interpret value `Month` for `x`. An entry with this name does not appear in `data`.
Traceback (most recent call last):
  File "C:\Users\24dan\Documents\AccountingCapstone\DFA\src\main\python\scripts\generate_graphs.py", line 168, in make_double_line
    sns.lineplot(x=x_name, y=y_name, data=df, label=y_name)
  File "C:\Users\24dan\AppData\Local\Packages\PythonSoftwareFoundation.Python.3.11_qbz5n2kfra8p0\LocalCache\local-packages\Python311\site-packages\seaborn\relational.py", line 485, in lineplot
    p = _LinePlotter(
        ^^^^^^^^^^^^^
  File "C:\Users\24dan\AppData\Local\Packages\PythonSoftwareFoundation.Python.3.11_qbz5n2kfra8p0\LocalCache\local-packages\Python311\site-packages\seaborn\relational.py", line 216, in __init__
    super().__init__(data=data, variables=variables)
  File "C:\Users\24dan\AppData\Local\Packages\PythonSoftwareFoundation.Python.3.11_qbz5n2kfra8p0\LocalCache\local-packages\Python311\site-packages\seaborn\_base.py", line 634, in __init__
    self.assign_variables(data, variables)
  File "C:\Users\24dan\AppData\Local\Packages\PythonSoftwareFoundation.Python.3.11_qbz5n2kfra8p0\LocalCache\local-packages\Python311\site-packages\seaborn\_base.py", line 679, in assign_variables
    plot_data = PlotData(data, variables)
                ^^^^^^^^^^^^^^^^^^^^^^^^^
  File "C:\Users\24dan\AppData\Local\Packages\PythonSoftwareFoundation.Python.3.11_qbz5n2kfra8p0\LocalCache\local-packages\Python311\site-packages\seaborn\_core\data.py", line 58, in __init__
    frame, names, ids = self._assign_variables(data, variables)
                        ^^^^^^^^^^^^^^^^^^^^^^^^^^^^^^^^^^^^^^^
  File "C:\Users\24dan\AppData\Local\Packages\PythonSoftwareFoundation.Python.3.11_qbz5n2kfra8p0\LocalCache\local-packages\Python311\site-packages\seaborn\_core\data.py", line 232, in _assign_variables
    raise ValueError(err)
ValueError: Could not interpret value `Month` for `x`. An entry with this name does not appear in `data`.

During handling of the above exception, another exception occurred:

Traceback (most recent call last):
  File "C:\Users\24dan\Documents\AccountingCapstone\DFA\src\main\python\scripts\generate_graphs.py", line 233, in <module>
    make_double_line(getDataFrame(str(sql_statement)), str(graph_name), 7, 14, graph_x_name, graph_y_name, graph_y2_name)
  File "C:\Users\24dan\Documents\AccountingCapstone\DFA\src\main\python\scripts\generate_graphs.py", line 176, in make_double_line
    raise RuntimeError("An error occurred while making double line graph: %s" % e)
RuntimeError: An error occurred while making double line graph: Could not interpret value `Month` for `x`. An entry with this name does not appear in `data`.
2024-04-15 02:09:36,660 - ERROR - An error occurred: An error occurred while making double line graph: Could not interpret value `Month` for `x`. An entry with this name does not appear in `data`.
Traceback (most recent call last):
  File "C:\Users\24dan\Documents\AccountingCapstone\DFA\src\main\python\scripts\generate_graphs.py", line 168, in make_double_line
    sns.lineplot(x=x_name, y=y_name, data=df, label=y_name)
  File "C:\Users\24dan\AppData\Local\Packages\PythonSoftwareFoundation.Python.3.11_qbz5n2kfra8p0\LocalCache\local-packages\Python311\site-packages\seaborn\relational.py", line 485, in lineplot
    p = _LinePlotter(
        ^^^^^^^^^^^^^
  File "C:\Users\24dan\AppData\Local\Packages\PythonSoftwareFoundation.Python.3.11_qbz5n2kfra8p0\LocalCache\local-packages\Python311\site-packages\seaborn\relational.py", line 216, in __init__
    super().__init__(data=data, variables=variables)
  File "C:\Users\24dan\AppData\Local\Packages\PythonSoftwareFoundation.Python.3.11_qbz5n2kfra8p0\LocalCache\local-packages\Python311\site-packages\seaborn\_base.py", line 634, in __init__
    self.assign_variables(data, variables)
  File "C:\Users\24dan\AppData\Local\Packages\PythonSoftwareFoundation.Python.3.11_qbz5n2kfra8p0\LocalCache\local-packages\Python311\site-packages\seaborn\_base.py", line 679, in assign_variables
    plot_data = PlotData(data, variables)
                ^^^^^^^^^^^^^^^^^^^^^^^^^
  File "C:\Users\24dan\AppData\Local\Packages\PythonSoftwareFoundation.Python.3.11_qbz5n2kfra8p0\LocalCache\local-packages\Python311\site-packages\seaborn\_core\data.py", line 58, in __init__
    frame, names, ids = self._assign_variables(data, variables)
                        ^^^^^^^^^^^^^^^^^^^^^^^^^^^^^^^^^^^^^^^
  File "C:\Users\24dan\AppData\Local\Packages\PythonSoftwareFoundation.Python.3.11_qbz5n2kfra8p0\LocalCache\local-packages\Python311\site-packages\seaborn\_core\data.py", line 232, in _assign_variables
    raise ValueError(err)
ValueError: Could not interpret value `Month` for `x`. An entry with this name does not appear in `data`.

During handling of the above exception, another exception occurred:

Traceback (most recent call last):
  File "C:\Users\24dan\Documents\AccountingCapstone\DFA\src\main\python\scripts\generate_graphs.py", line 233, in <module>
    make_double_line(getDataFrame(str(sql_statement)), str(graph_name), 7, 14, graph_x_name, graph_y_name, graph_y2_name)
  File "C:\Users\24dan\Documents\AccountingCapstone\DFA\src\main\python\scripts\generate_graphs.py", line 176, in make_double_line
    raise RuntimeError("An error occurred while making double line graph: %s" % e)
RuntimeError: An error occurred while making double line graph: Could not interpret value `Month` for `x`. An entry with this name does not appear in `data`.
2024-04-15 02:11:07,691 - ERROR - An error occurred: An error occurred while making double line graph: Could not interpret value `Month` for `x`. An entry with this name does not appear in `data`.
Traceback (most recent call last):
  File "C:\Users\24dan\Documents\AccountingCapstone\DFA\src\main\python\scripts\generate_graphs.py", line 168, in make_double_line
    sns.lineplot(x=x_name, y=y_name, data=df, label=y_name)
  File "C:\Users\24dan\AppData\Local\Packages\PythonSoftwareFoundation.Python.3.11_qbz5n2kfra8p0\LocalCache\local-packages\Python311\site-packages\seaborn\relational.py", line 485, in lineplot
    p = _LinePlotter(
        ^^^^^^^^^^^^^
  File "C:\Users\24dan\AppData\Local\Packages\PythonSoftwareFoundation.Python.3.11_qbz5n2kfra8p0\LocalCache\local-packages\Python311\site-packages\seaborn\relational.py", line 216, in __init__
    super().__init__(data=data, variables=variables)
  File "C:\Users\24dan\AppData\Local\Packages\PythonSoftwareFoundation.Python.3.11_qbz5n2kfra8p0\LocalCache\local-packages\Python311\site-packages\seaborn\_base.py", line 634, in __init__
    self.assign_variables(data, variables)
  File "C:\Users\24dan\AppData\Local\Packages\PythonSoftwareFoundation.Python.3.11_qbz5n2kfra8p0\LocalCache\local-packages\Python311\site-packages\seaborn\_base.py", line 679, in assign_variables
    plot_data = PlotData(data, variables)
                ^^^^^^^^^^^^^^^^^^^^^^^^^
  File "C:\Users\24dan\AppData\Local\Packages\PythonSoftwareFoundation.Python.3.11_qbz5n2kfra8p0\LocalCache\local-packages\Python311\site-packages\seaborn\_core\data.py", line 58, in __init__
    frame, names, ids = self._assign_variables(data, variables)
                        ^^^^^^^^^^^^^^^^^^^^^^^^^^^^^^^^^^^^^^^
  File "C:\Users\24dan\AppData\Local\Packages\PythonSoftwareFoundation.Python.3.11_qbz5n2kfra8p0\LocalCache\local-packages\Python311\site-packages\seaborn\_core\data.py", line 232, in _assign_variables
    raise ValueError(err)
ValueError: Could not interpret value `Month` for `x`. An entry with this name does not appear in `data`.

During handling of the above exception, another exception occurred:

Traceback (most recent call last):
  File "C:\Users\24dan\Documents\AccountingCapstone\DFA\src\main\python\scripts\generate_graphs.py", line 233, in <module>
    make_double_line(getDataFrame(str(sql_statement)), str(graph_name), 7, 14, graph_x_name, graph_y_name, graph_y2_name)
  File "C:\Users\24dan\Documents\AccountingCapstone\DFA\src\main\python\scripts\generate_graphs.py", line 176, in make_double_line
    raise RuntimeError("An error occurred while making double line graph: %s" % e)
RuntimeError: An error occurred while making double line graph: Could not interpret value `Month` for `x`. An entry with this name does not appear in `data`.
2024-04-15 02:11:40,996 - ERROR - An error occurred: An error occurred while making double line graph: Could not interpret value `Month` for `x`. An entry with this name does not appear in `data`.
Traceback (most recent call last):
  File "C:\Users\24dan\Documents\AccountingCapstone\DFA\src\main\python\scripts\generate_graphs.py", line 168, in make_double_line
    sns.lineplot(x=x_name, y=y_name, data=df, label=y_name)
  File "C:\Users\24dan\AppData\Local\Packages\PythonSoftwareFoundation.Python.3.11_qbz5n2kfra8p0\LocalCache\local-packages\Python311\site-packages\seaborn\relational.py", line 485, in lineplot
    p = _LinePlotter(
        ^^^^^^^^^^^^^
  File "C:\Users\24dan\AppData\Local\Packages\PythonSoftwareFoundation.Python.3.11_qbz5n2kfra8p0\LocalCache\local-packages\Python311\site-packages\seaborn\relational.py", line 216, in __init__
    super().__init__(data=data, variables=variables)
  File "C:\Users\24dan\AppData\Local\Packages\PythonSoftwareFoundation.Python.3.11_qbz5n2kfra8p0\LocalCache\local-packages\Python311\site-packages\seaborn\_base.py", line 634, in __init__
    self.assign_variables(data, variables)
  File "C:\Users\24dan\AppData\Local\Packages\PythonSoftwareFoundation.Python.3.11_qbz5n2kfra8p0\LocalCache\local-packages\Python311\site-packages\seaborn\_base.py", line 679, in assign_variables
    plot_data = PlotData(data, variables)
                ^^^^^^^^^^^^^^^^^^^^^^^^^
  File "C:\Users\24dan\AppData\Local\Packages\PythonSoftwareFoundation.Python.3.11_qbz5n2kfra8p0\LocalCache\local-packages\Python311\site-packages\seaborn\_core\data.py", line 58, in __init__
    frame, names, ids = self._assign_variables(data, variables)
                        ^^^^^^^^^^^^^^^^^^^^^^^^^^^^^^^^^^^^^^^
  File "C:\Users\24dan\AppData\Local\Packages\PythonSoftwareFoundation.Python.3.11_qbz5n2kfra8p0\LocalCache\local-packages\Python311\site-packages\seaborn\_core\data.py", line 232, in _assign_variables
    raise ValueError(err)
ValueError: Could not interpret value `Month` for `x`. An entry with this name does not appear in `data`.

During handling of the above exception, another exception occurred:

Traceback (most recent call last):
  File "C:\Users\24dan\Documents\AccountingCapstone\DFA\src\main\python\scripts\generate_graphs.py", line 233, in <module>
    make_double_line(getDataFrame(str(sql_statement)), str(graph_name), 7, 14, graph_x_name, graph_y_name, graph_y2_name)
  File "C:\Users\24dan\Documents\AccountingCapstone\DFA\src\main\python\scripts\generate_graphs.py", line 176, in make_double_line
    raise RuntimeError("An error occurred while making double line graph: %s" % e)
RuntimeError: An error occurred while making double line graph: Could not interpret value `Month` for `x`. An entry with this name does not appear in `data`.
2024-04-15 02:11:50,138 - ERROR - An error occurred: An error occurred while making double line graph: Could not interpret value `Month` for `x`. An entry with this name does not appear in `data`.
Traceback (most recent call last):
  File "C:\Users\24dan\Documents\AccountingCapstone\DFA\src\main\python\scripts\generate_graphs.py", line 168, in make_double_line
    sns.lineplot(x=x_name, y=y_name, data=df, label=y_name)
  File "C:\Users\24dan\AppData\Local\Packages\PythonSoftwareFoundation.Python.3.11_qbz5n2kfra8p0\LocalCache\local-packages\Python311\site-packages\seaborn\relational.py", line 485, in lineplot
    p = _LinePlotter(
        ^^^^^^^^^^^^^
  File "C:\Users\24dan\AppData\Local\Packages\PythonSoftwareFoundation.Python.3.11_qbz5n2kfra8p0\LocalCache\local-packages\Python311\site-packages\seaborn\relational.py", line 216, in __init__
    super().__init__(data=data, variables=variables)
  File "C:\Users\24dan\AppData\Local\Packages\PythonSoftwareFoundation.Python.3.11_qbz5n2kfra8p0\LocalCache\local-packages\Python311\site-packages\seaborn\_base.py", line 634, in __init__
    self.assign_variables(data, variables)
  File "C:\Users\24dan\AppData\Local\Packages\PythonSoftwareFoundation.Python.3.11_qbz5n2kfra8p0\LocalCache\local-packages\Python311\site-packages\seaborn\_base.py", line 679, in assign_variables
    plot_data = PlotData(data, variables)
                ^^^^^^^^^^^^^^^^^^^^^^^^^
  File "C:\Users\24dan\AppData\Local\Packages\PythonSoftwareFoundation.Python.3.11_qbz5n2kfra8p0\LocalCache\local-packages\Python311\site-packages\seaborn\_core\data.py", line 58, in __init__
    frame, names, ids = self._assign_variables(data, variables)
                        ^^^^^^^^^^^^^^^^^^^^^^^^^^^^^^^^^^^^^^^
  File "C:\Users\24dan\AppData\Local\Packages\PythonSoftwareFoundation.Python.3.11_qbz5n2kfra8p0\LocalCache\local-packages\Python311\site-packages\seaborn\_core\data.py", line 232, in _assign_variables
    raise ValueError(err)
ValueError: Could not interpret value `Month` for `x`. An entry with this name does not appear in `data`.

During handling of the above exception, another exception occurred:

Traceback (most recent call last):
  File "C:\Users\24dan\Documents\AccountingCapstone\DFA\src\main\python\scripts\generate_graphs.py", line 233, in <module>
    make_double_line(getDataFrame(str(sql_statement)), str(graph_name), 7, 14, graph_x_name, graph_y_name, graph_y2_name)
  File "C:\Users\24dan\Documents\AccountingCapstone\DFA\src\main\python\scripts\generate_graphs.py", line 176, in make_double_line
    raise RuntimeError("An error occurred while making double line graph: %s" % e)
RuntimeError: An error occurred while making double line graph: Could not interpret value `Month` for `x`. An entry with this name does not appear in `data`.
2024-04-15 02:12:34,476 - ERROR - An error occurred: An error occurred while making double line graph: Could not interpret value `Month` for `x`. An entry with this name does not appear in `data`.
Traceback (most recent call last):
  File "C:\Users\24dan\Documents\AccountingCapstone\DFA\src\main\python\scripts\generate_graphs.py", line 168, in make_double_line
    sns.lineplot(x=x_name, y=y_name, data=df, label=y_name)
  File "C:\Users\24dan\AppData\Local\Packages\PythonSoftwareFoundation.Python.3.11_qbz5n2kfra8p0\LocalCache\local-packages\Python311\site-packages\seaborn\relational.py", line 485, in lineplot
    p = _LinePlotter(
        ^^^^^^^^^^^^^
  File "C:\Users\24dan\AppData\Local\Packages\PythonSoftwareFoundation.Python.3.11_qbz5n2kfra8p0\LocalCache\local-packages\Python311\site-packages\seaborn\relational.py", line 216, in __init__
    super().__init__(data=data, variables=variables)
  File "C:\Users\24dan\AppData\Local\Packages\PythonSoftwareFoundation.Python.3.11_qbz5n2kfra8p0\LocalCache\local-packages\Python311\site-packages\seaborn\_base.py", line 634, in __init__
    self.assign_variables(data, variables)
  File "C:\Users\24dan\AppData\Local\Packages\PythonSoftwareFoundation.Python.3.11_qbz5n2kfra8p0\LocalCache\local-packages\Python311\site-packages\seaborn\_base.py", line 679, in assign_variables
    plot_data = PlotData(data, variables)
                ^^^^^^^^^^^^^^^^^^^^^^^^^
  File "C:\Users\24dan\AppData\Local\Packages\PythonSoftwareFoundation.Python.3.11_qbz5n2kfra8p0\LocalCache\local-packages\Python311\site-packages\seaborn\_core\data.py", line 58, in __init__
    frame, names, ids = self._assign_variables(data, variables)
                        ^^^^^^^^^^^^^^^^^^^^^^^^^^^^^^^^^^^^^^^
  File "C:\Users\24dan\AppData\Local\Packages\PythonSoftwareFoundation.Python.3.11_qbz5n2kfra8p0\LocalCache\local-packages\Python311\site-packages\seaborn\_core\data.py", line 232, in _assign_variables
    raise ValueError(err)
ValueError: Could not interpret value `Month` for `x`. An entry with this name does not appear in `data`.

During handling of the above exception, another exception occurred:

Traceback (most recent call last):
  File "C:\Users\24dan\Documents\AccountingCapstone\DFA\src\main\python\scripts\generate_graphs.py", line 233, in <module>
    make_double_line(getDataFrame(str(sql_statement)), str(graph_name), 7, 14, graph_x_name, graph_y_name, graph_y2_name)
  File "C:\Users\24dan\Documents\AccountingCapstone\DFA\src\main\python\scripts\generate_graphs.py", line 176, in make_double_line
    raise RuntimeError("An error occurred while making double line graph: %s" % e)
RuntimeError: An error occurred while making double line graph: Could not interpret value `Month` for `x`. An entry with this name does not appear in `data`.
2024-04-15 02:12:45,263 - ERROR - An error occurred: An error occurred while making double line graph: Could not interpret value `Month` for `x`. An entry with this name does not appear in `data`.
Traceback (most recent call last):
  File "C:\Users\24dan\Documents\AccountingCapstone\DFA\src\main\python\scripts\generate_graphs.py", line 168, in make_double_line
    sns.lineplot(x=x_name, y=y_name, data=df, label=y_name)
  File "C:\Users\24dan\AppData\Local\Packages\PythonSoftwareFoundation.Python.3.11_qbz5n2kfra8p0\LocalCache\local-packages\Python311\site-packages\seaborn\relational.py", line 485, in lineplot
    p = _LinePlotter(
        ^^^^^^^^^^^^^
  File "C:\Users\24dan\AppData\Local\Packages\PythonSoftwareFoundation.Python.3.11_qbz5n2kfra8p0\LocalCache\local-packages\Python311\site-packages\seaborn\relational.py", line 216, in __init__
    super().__init__(data=data, variables=variables)
  File "C:\Users\24dan\AppData\Local\Packages\PythonSoftwareFoundation.Python.3.11_qbz5n2kfra8p0\LocalCache\local-packages\Python311\site-packages\seaborn\_base.py", line 634, in __init__
    self.assign_variables(data, variables)
  File "C:\Users\24dan\AppData\Local\Packages\PythonSoftwareFoundation.Python.3.11_qbz5n2kfra8p0\LocalCache\local-packages\Python311\site-packages\seaborn\_base.py", line 679, in assign_variables
    plot_data = PlotData(data, variables)
                ^^^^^^^^^^^^^^^^^^^^^^^^^
  File "C:\Users\24dan\AppData\Local\Packages\PythonSoftwareFoundation.Python.3.11_qbz5n2kfra8p0\LocalCache\local-packages\Python311\site-packages\seaborn\_core\data.py", line 58, in __init__
    frame, names, ids = self._assign_variables(data, variables)
                        ^^^^^^^^^^^^^^^^^^^^^^^^^^^^^^^^^^^^^^^
  File "C:\Users\24dan\AppData\Local\Packages\PythonSoftwareFoundation.Python.3.11_qbz5n2kfra8p0\LocalCache\local-packages\Python311\site-packages\seaborn\_core\data.py", line 232, in _assign_variables
    raise ValueError(err)
ValueError: Could not interpret value `Month` for `x`. An entry with this name does not appear in `data`.

During handling of the above exception, another exception occurred:

Traceback (most recent call last):
  File "C:\Users\24dan\Documents\AccountingCapstone\DFA\src\main\python\scripts\generate_graphs.py", line 233, in <module>
    make_double_line(getDataFrame(str(sql_statement)), str(graph_name), 7, 14, graph_x_name, graph_y_name, graph_y2_name)
  File "C:\Users\24dan\Documents\AccountingCapstone\DFA\src\main\python\scripts\generate_graphs.py", line 176, in make_double_line
    raise RuntimeError("An error occurred while making double line graph: %s" % e)
RuntimeError: An error occurred while making double line graph: Could not interpret value `Month` for `x`. An entry with this name does not appear in `data`.
2024-04-15 02:14:19,432 - ERROR - An error occurred: An error occurred while making double line graph: Could not interpret value `Month` for `x`. An entry with this name does not appear in `data`.
Traceback (most recent call last):
  File "C:\Users\24dan\Documents\AccountingCapstone\DFA\src\main\python\scripts\generate_graphs.py", line 168, in make_double_line
    sns.lineplot(x=x_name, y=y_name, data=df, label=y_name)
  File "C:\Users\24dan\AppData\Local\Packages\PythonSoftwareFoundation.Python.3.11_qbz5n2kfra8p0\LocalCache\local-packages\Python311\site-packages\seaborn\relational.py", line 485, in lineplot
    p = _LinePlotter(
        ^^^^^^^^^^^^^
  File "C:\Users\24dan\AppData\Local\Packages\PythonSoftwareFoundation.Python.3.11_qbz5n2kfra8p0\LocalCache\local-packages\Python311\site-packages\seaborn\relational.py", line 216, in __init__
    super().__init__(data=data, variables=variables)
  File "C:\Users\24dan\AppData\Local\Packages\PythonSoftwareFoundation.Python.3.11_qbz5n2kfra8p0\LocalCache\local-packages\Python311\site-packages\seaborn\_base.py", line 634, in __init__
    self.assign_variables(data, variables)
  File "C:\Users\24dan\AppData\Local\Packages\PythonSoftwareFoundation.Python.3.11_qbz5n2kfra8p0\LocalCache\local-packages\Python311\site-packages\seaborn\_base.py", line 679, in assign_variables
    plot_data = PlotData(data, variables)
                ^^^^^^^^^^^^^^^^^^^^^^^^^
  File "C:\Users\24dan\AppData\Local\Packages\PythonSoftwareFoundation.Python.3.11_qbz5n2kfra8p0\LocalCache\local-packages\Python311\site-packages\seaborn\_core\data.py", line 58, in __init__
    frame, names, ids = self._assign_variables(data, variables)
                        ^^^^^^^^^^^^^^^^^^^^^^^^^^^^^^^^^^^^^^^
  File "C:\Users\24dan\AppData\Local\Packages\PythonSoftwareFoundation.Python.3.11_qbz5n2kfra8p0\LocalCache\local-packages\Python311\site-packages\seaborn\_core\data.py", line 232, in _assign_variables
    raise ValueError(err)
ValueError: Could not interpret value `Month` for `x`. An entry with this name does not appear in `data`.

During handling of the above exception, another exception occurred:

Traceback (most recent call last):
  File "C:\Users\24dan\Documents\AccountingCapstone\DFA\src\main\python\scripts\generate_graphs.py", line 233, in <module>
    make_double_line(getDataFrame(str(sql_statement)), str(graph_name), 7, 14, graph_x_name, graph_y_name, graph_y2_name)
  File "C:\Users\24dan\Documents\AccountingCapstone\DFA\src\main\python\scripts\generate_graphs.py", line 176, in make_double_line
    raise RuntimeError("An error occurred while making double line graph: %s" % e)
RuntimeError: An error occurred while making double line graph: Could not interpret value `Month` for `x`. An entry with this name does not appear in `data`.
2024-04-15 02:14:25,198 - ERROR - An error occurred: An error occurred while making double line graph: Could not interpret value `Month` for `x`. An entry with this name does not appear in `data`.
Traceback (most recent call last):
  File "C:\Users\24dan\Documents\AccountingCapstone\DFA\src\main\python\scripts\generate_graphs.py", line 168, in make_double_line
    sns.lineplot(x=x_name, y=y_name, data=df, label=y_name)
  File "C:\Users\24dan\AppData\Local\Packages\PythonSoftwareFoundation.Python.3.11_qbz5n2kfra8p0\LocalCache\local-packages\Python311\site-packages\seaborn\relational.py", line 485, in lineplot
    p = _LinePlotter(
        ^^^^^^^^^^^^^
  File "C:\Users\24dan\AppData\Local\Packages\PythonSoftwareFoundation.Python.3.11_qbz5n2kfra8p0\LocalCache\local-packages\Python311\site-packages\seaborn\relational.py", line 216, in __init__
    super().__init__(data=data, variables=variables)
  File "C:\Users\24dan\AppData\Local\Packages\PythonSoftwareFoundation.Python.3.11_qbz5n2kfra8p0\LocalCache\local-packages\Python311\site-packages\seaborn\_base.py", line 634, in __init__
    self.assign_variables(data, variables)
  File "C:\Users\24dan\AppData\Local\Packages\PythonSoftwareFoundation.Python.3.11_qbz5n2kfra8p0\LocalCache\local-packages\Python311\site-packages\seaborn\_base.py", line 679, in assign_variables
    plot_data = PlotData(data, variables)
                ^^^^^^^^^^^^^^^^^^^^^^^^^
  File "C:\Users\24dan\AppData\Local\Packages\PythonSoftwareFoundation.Python.3.11_qbz5n2kfra8p0\LocalCache\local-packages\Python311\site-packages\seaborn\_core\data.py", line 58, in __init__
    frame, names, ids = self._assign_variables(data, variables)
                        ^^^^^^^^^^^^^^^^^^^^^^^^^^^^^^^^^^^^^^^
  File "C:\Users\24dan\AppData\Local\Packages\PythonSoftwareFoundation.Python.3.11_qbz5n2kfra8p0\LocalCache\local-packages\Python311\site-packages\seaborn\_core\data.py", line 232, in _assign_variables
    raise ValueError(err)
ValueError: Could not interpret value `Month` for `x`. An entry with this name does not appear in `data`.

During handling of the above exception, another exception occurred:

Traceback (most recent call last):
  File "C:\Users\24dan\Documents\AccountingCapstone\DFA\src\main\python\scripts\generate_graphs.py", line 233, in <module>
    make_double_line(getDataFrame(str(sql_statement)), str(graph_name), 7, 14, graph_x_name, graph_y_name, graph_y2_name)
  File "C:\Users\24dan\Documents\AccountingCapstone\DFA\src\main\python\scripts\generate_graphs.py", line 176, in make_double_line
    raise RuntimeError("An error occurred while making double line graph: %s" % e)
RuntimeError: An error occurred while making double line graph: Could not interpret value `Month` for `x`. An entry with this name does not appear in `data`.
2024-04-15 02:17:23,643 - ERROR - An error occurred: An error occurred while making double line graph: Could not interpret value `Month` for `x`. An entry with this name does not appear in `data`.
Traceback (most recent call last):
  File "C:\Users\24dan\Documents\AccountingCapstone\DFA\src\main\python\scripts\generate_graphs.py", line 168, in make_double_line
    sns.lineplot(x=x_name, y=y_name, data=df, label=y_name)
  File "C:\Users\24dan\AppData\Local\Packages\PythonSoftwareFoundation.Python.3.11_qbz5n2kfra8p0\LocalCache\local-packages\Python311\site-packages\seaborn\relational.py", line 485, in lineplot
    p = _LinePlotter(
        ^^^^^^^^^^^^^
  File "C:\Users\24dan\AppData\Local\Packages\PythonSoftwareFoundation.Python.3.11_qbz5n2kfra8p0\LocalCache\local-packages\Python311\site-packages\seaborn\relational.py", line 216, in __init__
    super().__init__(data=data, variables=variables)
  File "C:\Users\24dan\AppData\Local\Packages\PythonSoftwareFoundation.Python.3.11_qbz5n2kfra8p0\LocalCache\local-packages\Python311\site-packages\seaborn\_base.py", line 634, in __init__
    self.assign_variables(data, variables)
  File "C:\Users\24dan\AppData\Local\Packages\PythonSoftwareFoundation.Python.3.11_qbz5n2kfra8p0\LocalCache\local-packages\Python311\site-packages\seaborn\_base.py", line 679, in assign_variables
    plot_data = PlotData(data, variables)
                ^^^^^^^^^^^^^^^^^^^^^^^^^
  File "C:\Users\24dan\AppData\Local\Packages\PythonSoftwareFoundation.Python.3.11_qbz5n2kfra8p0\LocalCache\local-packages\Python311\site-packages\seaborn\_core\data.py", line 58, in __init__
    frame, names, ids = self._assign_variables(data, variables)
                        ^^^^^^^^^^^^^^^^^^^^^^^^^^^^^^^^^^^^^^^
  File "C:\Users\24dan\AppData\Local\Packages\PythonSoftwareFoundation.Python.3.11_qbz5n2kfra8p0\LocalCache\local-packages\Python311\site-packages\seaborn\_core\data.py", line 232, in _assign_variables
    raise ValueError(err)
ValueError: Could not interpret value `Month` for `x`. An entry with this name does not appear in `data`.

During handling of the above exception, another exception occurred:

Traceback (most recent call last):
  File "C:\Users\24dan\Documents\AccountingCapstone\DFA\src\main\python\scripts\generate_graphs.py", line 233, in <module>
    make_double_line(getDataFrame(str(sql_statement)), str(graph_name), 7, 14, graph_x_name, graph_y_name, graph_y2_name)
  File "C:\Users\24dan\Documents\AccountingCapstone\DFA\src\main\python\scripts\generate_graphs.py", line 176, in make_double_line
    raise RuntimeError("An error occurred while making double line graph: %s" % e)
RuntimeError: An error occurred while making double line graph: Could not interpret value `Month` for `x`. An entry with this name does not appear in `data`.
2024-04-15 02:18:38,521 - ERROR - An error occurred: An error occurred while making double line graph: Could not interpret value `Month` for `x`. An entry with this name does not appear in `data`.
Traceback (most recent call last):
  File "C:\Users\24dan\Documents\AccountingCapstone\DFA\src\main\python\scripts\generate_graphs.py", line 168, in make_double_line
    sns.lineplot(x=x_name, y=y_name, data=df, label=y_name)
  File "C:\Users\24dan\AppData\Local\Packages\PythonSoftwareFoundation.Python.3.11_qbz5n2kfra8p0\LocalCache\local-packages\Python311\site-packages\seaborn\relational.py", line 485, in lineplot
    p = _LinePlotter(
        ^^^^^^^^^^^^^
  File "C:\Users\24dan\AppData\Local\Packages\PythonSoftwareFoundation.Python.3.11_qbz5n2kfra8p0\LocalCache\local-packages\Python311\site-packages\seaborn\relational.py", line 216, in __init__
    super().__init__(data=data, variables=variables)
  File "C:\Users\24dan\AppData\Local\Packages\PythonSoftwareFoundation.Python.3.11_qbz5n2kfra8p0\LocalCache\local-packages\Python311\site-packages\seaborn\_base.py", line 634, in __init__
    self.assign_variables(data, variables)
  File "C:\Users\24dan\AppData\Local\Packages\PythonSoftwareFoundation.Python.3.11_qbz5n2kfra8p0\LocalCache\local-packages\Python311\site-packages\seaborn\_base.py", line 679, in assign_variables
    plot_data = PlotData(data, variables)
                ^^^^^^^^^^^^^^^^^^^^^^^^^
  File "C:\Users\24dan\AppData\Local\Packages\PythonSoftwareFoundation.Python.3.11_qbz5n2kfra8p0\LocalCache\local-packages\Python311\site-packages\seaborn\_core\data.py", line 58, in __init__
    frame, names, ids = self._assign_variables(data, variables)
                        ^^^^^^^^^^^^^^^^^^^^^^^^^^^^^^^^^^^^^^^
  File "C:\Users\24dan\AppData\Local\Packages\PythonSoftwareFoundation.Python.3.11_qbz5n2kfra8p0\LocalCache\local-packages\Python311\site-packages\seaborn\_core\data.py", line 232, in _assign_variables
    raise ValueError(err)
ValueError: Could not interpret value `Month` for `x`. An entry with this name does not appear in `data`.

During handling of the above exception, another exception occurred:

Traceback (most recent call last):
  File "C:\Users\24dan\Documents\AccountingCapstone\DFA\src\main\python\scripts\generate_graphs.py", line 233, in <module>
    make_double_line(getDataFrame(str(sql_statement)), str(graph_name), 7, 14, graph_x_name, graph_y_name, graph_y2_name)
  File "C:\Users\24dan\Documents\AccountingCapstone\DFA\src\main\python\scripts\generate_graphs.py", line 176, in make_double_line
    raise RuntimeError("An error occurred while making double line graph: %s" % e)
RuntimeError: An error occurred while making double line graph: Could not interpret value `Month` for `x`. An entry with this name does not appear in `data`.
2024-04-15 02:18:44,857 - ERROR - An error occurred: An error occurred while making double line graph: Could not interpret value `Month` for `x`. An entry with this name does not appear in `data`.
Traceback (most recent call last):
  File "C:\Users\24dan\Documents\AccountingCapstone\DFA\src\main\python\scripts\generate_graphs.py", line 168, in make_double_line
    sns.lineplot(x=x_name, y=y_name, data=df, label=y_name)
  File "C:\Users\24dan\AppData\Local\Packages\PythonSoftwareFoundation.Python.3.11_qbz5n2kfra8p0\LocalCache\local-packages\Python311\site-packages\seaborn\relational.py", line 485, in lineplot
    p = _LinePlotter(
        ^^^^^^^^^^^^^
  File "C:\Users\24dan\AppData\Local\Packages\PythonSoftwareFoundation.Python.3.11_qbz5n2kfra8p0\LocalCache\local-packages\Python311\site-packages\seaborn\relational.py", line 216, in __init__
    super().__init__(data=data, variables=variables)
  File "C:\Users\24dan\AppData\Local\Packages\PythonSoftwareFoundation.Python.3.11_qbz5n2kfra8p0\LocalCache\local-packages\Python311\site-packages\seaborn\_base.py", line 634, in __init__
    self.assign_variables(data, variables)
  File "C:\Users\24dan\AppData\Local\Packages\PythonSoftwareFoundation.Python.3.11_qbz5n2kfra8p0\LocalCache\local-packages\Python311\site-packages\seaborn\_base.py", line 679, in assign_variables
    plot_data = PlotData(data, variables)
                ^^^^^^^^^^^^^^^^^^^^^^^^^
  File "C:\Users\24dan\AppData\Local\Packages\PythonSoftwareFoundation.Python.3.11_qbz5n2kfra8p0\LocalCache\local-packages\Python311\site-packages\seaborn\_core\data.py", line 58, in __init__
    frame, names, ids = self._assign_variables(data, variables)
                        ^^^^^^^^^^^^^^^^^^^^^^^^^^^^^^^^^^^^^^^
  File "C:\Users\24dan\AppData\Local\Packages\PythonSoftwareFoundation.Python.3.11_qbz5n2kfra8p0\LocalCache\local-packages\Python311\site-packages\seaborn\_core\data.py", line 232, in _assign_variables
    raise ValueError(err)
ValueError: Could not interpret value `Month` for `x`. An entry with this name does not appear in `data`.

During handling of the above exception, another exception occurred:

Traceback (most recent call last):
  File "C:\Users\24dan\Documents\AccountingCapstone\DFA\src\main\python\scripts\generate_graphs.py", line 233, in <module>
    make_double_line(getDataFrame(str(sql_statement)), str(graph_name), 7, 14, graph_x_name, graph_y_name, graph_y2_name)
  File "C:\Users\24dan\Documents\AccountingCapstone\DFA\src\main\python\scripts\generate_graphs.py", line 176, in make_double_line
    raise RuntimeError("An error occurred while making double line graph: %s" % e)
RuntimeError: An error occurred while making double line graph: Could not interpret value `Month` for `x`. An entry with this name does not appear in `data`.
2024-04-15 02:18:50,235 - ERROR - An error occurred: An error occurred while making double line graph: Could not interpret value `Month` for `x`. An entry with this name does not appear in `data`.
Traceback (most recent call last):
  File "C:\Users\24dan\Documents\AccountingCapstone\DFA\src\main\python\scripts\generate_graphs.py", line 168, in make_double_line
    sns.lineplot(x=x_name, y=y_name, data=df, label=y_name)
  File "C:\Users\24dan\AppData\Local\Packages\PythonSoftwareFoundation.Python.3.11_qbz5n2kfra8p0\LocalCache\local-packages\Python311\site-packages\seaborn\relational.py", line 485, in lineplot
    p = _LinePlotter(
        ^^^^^^^^^^^^^
  File "C:\Users\24dan\AppData\Local\Packages\PythonSoftwareFoundation.Python.3.11_qbz5n2kfra8p0\LocalCache\local-packages\Python311\site-packages\seaborn\relational.py", line 216, in __init__
    super().__init__(data=data, variables=variables)
  File "C:\Users\24dan\AppData\Local\Packages\PythonSoftwareFoundation.Python.3.11_qbz5n2kfra8p0\LocalCache\local-packages\Python311\site-packages\seaborn\_base.py", line 634, in __init__
    self.assign_variables(data, variables)
  File "C:\Users\24dan\AppData\Local\Packages\PythonSoftwareFoundation.Python.3.11_qbz5n2kfra8p0\LocalCache\local-packages\Python311\site-packages\seaborn\_base.py", line 679, in assign_variables
    plot_data = PlotData(data, variables)
                ^^^^^^^^^^^^^^^^^^^^^^^^^
  File "C:\Users\24dan\AppData\Local\Packages\PythonSoftwareFoundation.Python.3.11_qbz5n2kfra8p0\LocalCache\local-packages\Python311\site-packages\seaborn\_core\data.py", line 58, in __init__
    frame, names, ids = self._assign_variables(data, variables)
                        ^^^^^^^^^^^^^^^^^^^^^^^^^^^^^^^^^^^^^^^
  File "C:\Users\24dan\AppData\Local\Packages\PythonSoftwareFoundation.Python.3.11_qbz5n2kfra8p0\LocalCache\local-packages\Python311\site-packages\seaborn\_core\data.py", line 232, in _assign_variables
    raise ValueError(err)
ValueError: Could not interpret value `Month` for `x`. An entry with this name does not appear in `data`.

During handling of the above exception, another exception occurred:

Traceback (most recent call last):
  File "C:\Users\24dan\Documents\AccountingCapstone\DFA\src\main\python\scripts\generate_graphs.py", line 233, in <module>
    make_double_line(getDataFrame(str(sql_statement)), str(graph_name), 7, 14, graph_x_name, graph_y_name, graph_y2_name)
  File "C:\Users\24dan\Documents\AccountingCapstone\DFA\src\main\python\scripts\generate_graphs.py", line 176, in make_double_line
    raise RuntimeError("An error occurred while making double line graph: %s" % e)
RuntimeError: An error occurred while making double line graph: Could not interpret value `Month` for `x`. An entry with this name does not appear in `data`.
2024-04-15 02:19:08,751 - ERROR - An error occurred: An error occurred while making double line graph: Could not interpret value `Month` for `x`. An entry with this name does not appear in `data`.
Traceback (most recent call last):
  File "C:\Users\24dan\Documents\AccountingCapstone\DFA\src\main\python\scripts\generate_graphs.py", line 168, in make_double_line
    sns.lineplot(x=x_name, y=y_name, data=df, label=y_name)
  File "C:\Users\24dan\AppData\Local\Packages\PythonSoftwareFoundation.Python.3.11_qbz5n2kfra8p0\LocalCache\local-packages\Python311\site-packages\seaborn\relational.py", line 485, in lineplot
    p = _LinePlotter(
        ^^^^^^^^^^^^^
  File "C:\Users\24dan\AppData\Local\Packages\PythonSoftwareFoundation.Python.3.11_qbz5n2kfra8p0\LocalCache\local-packages\Python311\site-packages\seaborn\relational.py", line 216, in __init__
    super().__init__(data=data, variables=variables)
  File "C:\Users\24dan\AppData\Local\Packages\PythonSoftwareFoundation.Python.3.11_qbz5n2kfra8p0\LocalCache\local-packages\Python311\site-packages\seaborn\_base.py", line 634, in __init__
    self.assign_variables(data, variables)
  File "C:\Users\24dan\AppData\Local\Packages\PythonSoftwareFoundation.Python.3.11_qbz5n2kfra8p0\LocalCache\local-packages\Python311\site-packages\seaborn\_base.py", line 679, in assign_variables
    plot_data = PlotData(data, variables)
                ^^^^^^^^^^^^^^^^^^^^^^^^^
  File "C:\Users\24dan\AppData\Local\Packages\PythonSoftwareFoundation.Python.3.11_qbz5n2kfra8p0\LocalCache\local-packages\Python311\site-packages\seaborn\_core\data.py", line 58, in __init__
    frame, names, ids = self._assign_variables(data, variables)
                        ^^^^^^^^^^^^^^^^^^^^^^^^^^^^^^^^^^^^^^^
  File "C:\Users\24dan\AppData\Local\Packages\PythonSoftwareFoundation.Python.3.11_qbz5n2kfra8p0\LocalCache\local-packages\Python311\site-packages\seaborn\_core\data.py", line 232, in _assign_variables
    raise ValueError(err)
ValueError: Could not interpret value `Month` for `x`. An entry with this name does not appear in `data`.

During handling of the above exception, another exception occurred:

Traceback (most recent call last):
  File "C:\Users\24dan\Documents\AccountingCapstone\DFA\src\main\python\scripts\generate_graphs.py", line 233, in <module>
    make_double_line(getDataFrame(str(sql_statement)), str(graph_name), 7, 14, graph_x_name, graph_y_name, graph_y2_name)
  File "C:\Users\24dan\Documents\AccountingCapstone\DFA\src\main\python\scripts\generate_graphs.py", line 176, in make_double_line
    raise RuntimeError("An error occurred while making double line graph: %s" % e)
RuntimeError: An error occurred while making double line graph: Could not interpret value `Month` for `x`. An entry with this name does not appear in `data`.
2024-04-15 02:20:14,310 - ERROR - An error occurred: An error occurred while making double line graph: Could not interpret value `Month` for `x`. An entry with this name does not appear in `data`.
Traceback (most recent call last):
  File "C:\Users\24dan\Documents\AccountingCapstone\DFA\src\main\python\scripts\generate_graphs.py", line 168, in make_double_line
    sns.lineplot(x=x_name, y=y_name, data=df, label=y_name)
  File "C:\Users\24dan\AppData\Local\Packages\PythonSoftwareFoundation.Python.3.11_qbz5n2kfra8p0\LocalCache\local-packages\Python311\site-packages\seaborn\relational.py", line 485, in lineplot
    p = _LinePlotter(
        ^^^^^^^^^^^^^
  File "C:\Users\24dan\AppData\Local\Packages\PythonSoftwareFoundation.Python.3.11_qbz5n2kfra8p0\LocalCache\local-packages\Python311\site-packages\seaborn\relational.py", line 216, in __init__
    super().__init__(data=data, variables=variables)
  File "C:\Users\24dan\AppData\Local\Packages\PythonSoftwareFoundation.Python.3.11_qbz5n2kfra8p0\LocalCache\local-packages\Python311\site-packages\seaborn\_base.py", line 634, in __init__
    self.assign_variables(data, variables)
  File "C:\Users\24dan\AppData\Local\Packages\PythonSoftwareFoundation.Python.3.11_qbz5n2kfra8p0\LocalCache\local-packages\Python311\site-packages\seaborn\_base.py", line 679, in assign_variables
    plot_data = PlotData(data, variables)
                ^^^^^^^^^^^^^^^^^^^^^^^^^
  File "C:\Users\24dan\AppData\Local\Packages\PythonSoftwareFoundation.Python.3.11_qbz5n2kfra8p0\LocalCache\local-packages\Python311\site-packages\seaborn\_core\data.py", line 58, in __init__
    frame, names, ids = self._assign_variables(data, variables)
                        ^^^^^^^^^^^^^^^^^^^^^^^^^^^^^^^^^^^^^^^
  File "C:\Users\24dan\AppData\Local\Packages\PythonSoftwareFoundation.Python.3.11_qbz5n2kfra8p0\LocalCache\local-packages\Python311\site-packages\seaborn\_core\data.py", line 232, in _assign_variables
    raise ValueError(err)
ValueError: Could not interpret value `Month` for `x`. An entry with this name does not appear in `data`.

During handling of the above exception, another exception occurred:

Traceback (most recent call last):
  File "C:\Users\24dan\Documents\AccountingCapstone\DFA\src\main\python\scripts\generate_graphs.py", line 233, in <module>
    make_double_line(getDataFrame(str(sql_statement)), str(graph_name), 7, 14, graph_x_name, graph_y_name, graph_y2_name)
  File "C:\Users\24dan\Documents\AccountingCapstone\DFA\src\main\python\scripts\generate_graphs.py", line 176, in make_double_line
    raise RuntimeError("An error occurred while making double line graph: %s" % e)
RuntimeError: An error occurred while making double line graph: Could not interpret value `Month` for `x`. An entry with this name does not appear in `data`.
2024-04-15 02:20:26,628 - ERROR - An error occurred: An error occurred while making double line graph: Could not interpret value `Month` for `x`. An entry with this name does not appear in `data`.
Traceback (most recent call last):
  File "C:\Users\24dan\Documents\AccountingCapstone\DFA\src\main\python\scripts\generate_graphs.py", line 168, in make_double_line
    sns.lineplot(x=x_name, y=y_name, data=df, label=y_name)
  File "C:\Users\24dan\AppData\Local\Packages\PythonSoftwareFoundation.Python.3.11_qbz5n2kfra8p0\LocalCache\local-packages\Python311\site-packages\seaborn\relational.py", line 485, in lineplot
    p = _LinePlotter(
        ^^^^^^^^^^^^^
  File "C:\Users\24dan\AppData\Local\Packages\PythonSoftwareFoundation.Python.3.11_qbz5n2kfra8p0\LocalCache\local-packages\Python311\site-packages\seaborn\relational.py", line 216, in __init__
    super().__init__(data=data, variables=variables)
  File "C:\Users\24dan\AppData\Local\Packages\PythonSoftwareFoundation.Python.3.11_qbz5n2kfra8p0\LocalCache\local-packages\Python311\site-packages\seaborn\_base.py", line 634, in __init__
    self.assign_variables(data, variables)
  File "C:\Users\24dan\AppData\Local\Packages\PythonSoftwareFoundation.Python.3.11_qbz5n2kfra8p0\LocalCache\local-packages\Python311\site-packages\seaborn\_base.py", line 679, in assign_variables
    plot_data = PlotData(data, variables)
                ^^^^^^^^^^^^^^^^^^^^^^^^^
  File "C:\Users\24dan\AppData\Local\Packages\PythonSoftwareFoundation.Python.3.11_qbz5n2kfra8p0\LocalCache\local-packages\Python311\site-packages\seaborn\_core\data.py", line 58, in __init__
    frame, names, ids = self._assign_variables(data, variables)
                        ^^^^^^^^^^^^^^^^^^^^^^^^^^^^^^^^^^^^^^^
  File "C:\Users\24dan\AppData\Local\Packages\PythonSoftwareFoundation.Python.3.11_qbz5n2kfra8p0\LocalCache\local-packages\Python311\site-packages\seaborn\_core\data.py", line 232, in _assign_variables
    raise ValueError(err)
ValueError: Could not interpret value `Month` for `x`. An entry with this name does not appear in `data`.

During handling of the above exception, another exception occurred:

Traceback (most recent call last):
  File "C:\Users\24dan\Documents\AccountingCapstone\DFA\src\main\python\scripts\generate_graphs.py", line 233, in <module>
    make_double_line(getDataFrame(str(sql_statement)), str(graph_name), 7, 14, graph_x_name, graph_y_name, graph_y2_name)
  File "C:\Users\24dan\Documents\AccountingCapstone\DFA\src\main\python\scripts\generate_graphs.py", line 176, in make_double_line
    raise RuntimeError("An error occurred while making double line graph: %s" % e)
RuntimeError: An error occurred while making double line graph: Could not interpret value `Month` for `x`. An entry with this name does not appear in `data`.
2024-04-15 02:20:50,191 - ERROR - An error occurred: An error occurred while making double line graph: Could not interpret value `Month` for `x`. An entry with this name does not appear in `data`.
Traceback (most recent call last):
  File "C:\Users\24dan\Documents\AccountingCapstone\DFA\src\main\python\scripts\generate_graphs.py", line 168, in make_double_line
    sns.lineplot(x=x_name, y=y_name, data=df, label=y_name)
  File "C:\Users\24dan\AppData\Local\Packages\PythonSoftwareFoundation.Python.3.11_qbz5n2kfra8p0\LocalCache\local-packages\Python311\site-packages\seaborn\relational.py", line 485, in lineplot
    p = _LinePlotter(
        ^^^^^^^^^^^^^
  File "C:\Users\24dan\AppData\Local\Packages\PythonSoftwareFoundation.Python.3.11_qbz5n2kfra8p0\LocalCache\local-packages\Python311\site-packages\seaborn\relational.py", line 216, in __init__
    super().__init__(data=data, variables=variables)
  File "C:\Users\24dan\AppData\Local\Packages\PythonSoftwareFoundation.Python.3.11_qbz5n2kfra8p0\LocalCache\local-packages\Python311\site-packages\seaborn\_base.py", line 634, in __init__
    self.assign_variables(data, variables)
  File "C:\Users\24dan\AppData\Local\Packages\PythonSoftwareFoundation.Python.3.11_qbz5n2kfra8p0\LocalCache\local-packages\Python311\site-packages\seaborn\_base.py", line 679, in assign_variables
    plot_data = PlotData(data, variables)
                ^^^^^^^^^^^^^^^^^^^^^^^^^
  File "C:\Users\24dan\AppData\Local\Packages\PythonSoftwareFoundation.Python.3.11_qbz5n2kfra8p0\LocalCache\local-packages\Python311\site-packages\seaborn\_core\data.py", line 58, in __init__
    frame, names, ids = self._assign_variables(data, variables)
                        ^^^^^^^^^^^^^^^^^^^^^^^^^^^^^^^^^^^^^^^
  File "C:\Users\24dan\AppData\Local\Packages\PythonSoftwareFoundation.Python.3.11_qbz5n2kfra8p0\LocalCache\local-packages\Python311\site-packages\seaborn\_core\data.py", line 232, in _assign_variables
    raise ValueError(err)
ValueError: Could not interpret value `Month` for `x`. An entry with this name does not appear in `data`.

During handling of the above exception, another exception occurred:

Traceback (most recent call last):
  File "C:\Users\24dan\Documents\AccountingCapstone\DFA\src\main\python\scripts\generate_graphs.py", line 233, in <module>
    make_double_line(getDataFrame(str(sql_statement)), str(graph_name), 7, 14, graph_x_name, graph_y_name, graph_y2_name)
  File "C:\Users\24dan\Documents\AccountingCapstone\DFA\src\main\python\scripts\generate_graphs.py", line 176, in make_double_line
    raise RuntimeError("An error occurred while making double line graph: %s" % e)
RuntimeError: An error occurred while making double line graph: Could not interpret value `Month` for `x`. An entry with this name does not appear in `data`.
2024-04-15 02:22:15,390 - ERROR - An error occurred: An error occurred while making double line graph: Could not interpret value `Month` for `x`. An entry with this name does not appear in `data`.
Traceback (most recent call last):
  File "C:\Users\24dan\Documents\AccountingCapstone\DFA\src\main\python\scripts\generate_graphs.py", line 168, in make_double_line
    sns.lineplot(x=x_name, y=y_name, data=df, label=y_name)
  File "C:\Users\24dan\AppData\Local\Packages\PythonSoftwareFoundation.Python.3.11_qbz5n2kfra8p0\LocalCache\local-packages\Python311\site-packages\seaborn\relational.py", line 485, in lineplot
    p = _LinePlotter(
        ^^^^^^^^^^^^^
  File "C:\Users\24dan\AppData\Local\Packages\PythonSoftwareFoundation.Python.3.11_qbz5n2kfra8p0\LocalCache\local-packages\Python311\site-packages\seaborn\relational.py", line 216, in __init__
    super().__init__(data=data, variables=variables)
  File "C:\Users\24dan\AppData\Local\Packages\PythonSoftwareFoundation.Python.3.11_qbz5n2kfra8p0\LocalCache\local-packages\Python311\site-packages\seaborn\_base.py", line 634, in __init__
    self.assign_variables(data, variables)
  File "C:\Users\24dan\AppData\Local\Packages\PythonSoftwareFoundation.Python.3.11_qbz5n2kfra8p0\LocalCache\local-packages\Python311\site-packages\seaborn\_base.py", line 679, in assign_variables
    plot_data = PlotData(data, variables)
                ^^^^^^^^^^^^^^^^^^^^^^^^^
  File "C:\Users\24dan\AppData\Local\Packages\PythonSoftwareFoundation.Python.3.11_qbz5n2kfra8p0\LocalCache\local-packages\Python311\site-packages\seaborn\_core\data.py", line 58, in __init__
    frame, names, ids = self._assign_variables(data, variables)
                        ^^^^^^^^^^^^^^^^^^^^^^^^^^^^^^^^^^^^^^^
  File "C:\Users\24dan\AppData\Local\Packages\PythonSoftwareFoundation.Python.3.11_qbz5n2kfra8p0\LocalCache\local-packages\Python311\site-packages\seaborn\_core\data.py", line 232, in _assign_variables
    raise ValueError(err)
ValueError: Could not interpret value `Month` for `x`. An entry with this name does not appear in `data`.

During handling of the above exception, another exception occurred:

Traceback (most recent call last):
  File "C:\Users\24dan\Documents\AccountingCapstone\DFA\src\main\python\scripts\generate_graphs.py", line 233, in <module>
    make_double_line(getDataFrame(str(sql_statement)), str(graph_name), 7, 14, graph_x_name, graph_y_name, graph_y2_name)
  File "C:\Users\24dan\Documents\AccountingCapstone\DFA\src\main\python\scripts\generate_graphs.py", line 176, in make_double_line
    raise RuntimeError("An error occurred while making double line graph: %s" % e)
RuntimeError: An error occurred while making double line graph: Could not interpret value `Month` for `x`. An entry with this name does not appear in `data`.
2024-04-15 10:05:17,289 - ERROR - An error occurred: An error occurred while making double line graph: Could not interpret value `Month` for `x`. An entry with this name does not appear in `data`.
Traceback (most recent call last):
  File "C:\Users\24dan\Documents\AccountingCapstone\DFA\src\main\python\scripts\generate_graphs.py", line 168, in make_double_line
    sns.lineplot(x=x_name, y=y_name, data=df, label=y_name)
  File "C:\Users\24dan\AppData\Local\Packages\PythonSoftwareFoundation.Python.3.11_qbz5n2kfra8p0\LocalCache\local-packages\Python311\site-packages\seaborn\relational.py", line 485, in lineplot
    p = _LinePlotter(
        ^^^^^^^^^^^^^
  File "C:\Users\24dan\AppData\Local\Packages\PythonSoftwareFoundation.Python.3.11_qbz5n2kfra8p0\LocalCache\local-packages\Python311\site-packages\seaborn\relational.py", line 216, in __init__
    super().__init__(data=data, variables=variables)
  File "C:\Users\24dan\AppData\Local\Packages\PythonSoftwareFoundation.Python.3.11_qbz5n2kfra8p0\LocalCache\local-packages\Python311\site-packages\seaborn\_base.py", line 634, in __init__
    self.assign_variables(data, variables)
  File "C:\Users\24dan\AppData\Local\Packages\PythonSoftwareFoundation.Python.3.11_qbz5n2kfra8p0\LocalCache\local-packages\Python311\site-packages\seaborn\_base.py", line 679, in assign_variables
    plot_data = PlotData(data, variables)
                ^^^^^^^^^^^^^^^^^^^^^^^^^
  File "C:\Users\24dan\AppData\Local\Packages\PythonSoftwareFoundation.Python.3.11_qbz5n2kfra8p0\LocalCache\local-packages\Python311\site-packages\seaborn\_core\data.py", line 58, in __init__
    frame, names, ids = self._assign_variables(data, variables)
                        ^^^^^^^^^^^^^^^^^^^^^^^^^^^^^^^^^^^^^^^
  File "C:\Users\24dan\AppData\Local\Packages\PythonSoftwareFoundation.Python.3.11_qbz5n2kfra8p0\LocalCache\local-packages\Python311\site-packages\seaborn\_core\data.py", line 232, in _assign_variables
    raise ValueError(err)
ValueError: Could not interpret value `Month` for `x`. An entry with this name does not appear in `data`.

During handling of the above exception, another exception occurred:

Traceback (most recent call last):
  File "C:\Users\24dan\Documents\AccountingCapstone\DFA\src\main\python\scripts\generate_graphs.py", line 233, in <module>
    make_double_line(getDataFrame(str(sql_statement)), str(graph_name), 7, 14, graph_x_name, graph_y_name, graph_y2_name)
  File "C:\Users\24dan\Documents\AccountingCapstone\DFA\src\main\python\scripts\generate_graphs.py", line 176, in make_double_line
    raise RuntimeError("An error occurred while making double line graph: %s" % e)
RuntimeError: An error occurred while making double line graph: Could not interpret value `Month` for `x`. An entry with this name does not appear in `data`.
2024-04-15 10:05:34,563 - ERROR - An error occurred: An error occurred while making double line graph: Could not interpret value `Month` for `x`. An entry with this name does not appear in `data`.
Traceback (most recent call last):
  File "C:\Users\24dan\Documents\AccountingCapstone\DFA\src\main\python\scripts\generate_graphs.py", line 168, in make_double_line
    sns.lineplot(x=x_name, y=y_name, data=df, label=y_name)
  File "C:\Users\24dan\AppData\Local\Packages\PythonSoftwareFoundation.Python.3.11_qbz5n2kfra8p0\LocalCache\local-packages\Python311\site-packages\seaborn\relational.py", line 485, in lineplot
    p = _LinePlotter(
        ^^^^^^^^^^^^^
  File "C:\Users\24dan\AppData\Local\Packages\PythonSoftwareFoundation.Python.3.11_qbz5n2kfra8p0\LocalCache\local-packages\Python311\site-packages\seaborn\relational.py", line 216, in __init__
    super().__init__(data=data, variables=variables)
  File "C:\Users\24dan\AppData\Local\Packages\PythonSoftwareFoundation.Python.3.11_qbz5n2kfra8p0\LocalCache\local-packages\Python311\site-packages\seaborn\_base.py", line 634, in __init__
    self.assign_variables(data, variables)
  File "C:\Users\24dan\AppData\Local\Packages\PythonSoftwareFoundation.Python.3.11_qbz5n2kfra8p0\LocalCache\local-packages\Python311\site-packages\seaborn\_base.py", line 679, in assign_variables
    plot_data = PlotData(data, variables)
                ^^^^^^^^^^^^^^^^^^^^^^^^^
  File "C:\Users\24dan\AppData\Local\Packages\PythonSoftwareFoundation.Python.3.11_qbz5n2kfra8p0\LocalCache\local-packages\Python311\site-packages\seaborn\_core\data.py", line 58, in __init__
    frame, names, ids = self._assign_variables(data, variables)
                        ^^^^^^^^^^^^^^^^^^^^^^^^^^^^^^^^^^^^^^^
  File "C:\Users\24dan\AppData\Local\Packages\PythonSoftwareFoundation.Python.3.11_qbz5n2kfra8p0\LocalCache\local-packages\Python311\site-packages\seaborn\_core\data.py", line 232, in _assign_variables
    raise ValueError(err)
ValueError: Could not interpret value `Month` for `x`. An entry with this name does not appear in `data`.

During handling of the above exception, another exception occurred:

Traceback (most recent call last):
  File "C:\Users\24dan\Documents\AccountingCapstone\DFA\src\main\python\scripts\generate_graphs.py", line 233, in <module>
    make_double_line(getDataFrame(str(sql_statement)), str(graph_name), 7, 14, graph_x_name, graph_y_name, graph_y2_name)
  File "C:\Users\24dan\Documents\AccountingCapstone\DFA\src\main\python\scripts\generate_graphs.py", line 176, in make_double_line
    raise RuntimeError("An error occurred while making double line graph: %s" % e)
RuntimeError: An error occurred while making double line graph: Could not interpret value `Month` for `x`. An entry with this name does not appear in `data`.
2024-04-15 10:09:26,057 - ERROR - An error occurred: An error occurred while making double line graph: Could not interpret value `Month` for `x`. An entry with this name does not appear in `data`.
Traceback (most recent call last):
  File "C:\Users\24dan\Documents\AccountingCapstone\DFA\src\main\python\scripts\generate_graphs.py", line 168, in make_double_line
    sns.lineplot(x=x_name, y=y_name, data=df, label=y_name)
  File "C:\Users\24dan\AppData\Local\Packages\PythonSoftwareFoundation.Python.3.11_qbz5n2kfra8p0\LocalCache\local-packages\Python311\site-packages\seaborn\relational.py", line 485, in lineplot
    p = _LinePlotter(
        ^^^^^^^^^^^^^
  File "C:\Users\24dan\AppData\Local\Packages\PythonSoftwareFoundation.Python.3.11_qbz5n2kfra8p0\LocalCache\local-packages\Python311\site-packages\seaborn\relational.py", line 216, in __init__
    super().__init__(data=data, variables=variables)
  File "C:\Users\24dan\AppData\Local\Packages\PythonSoftwareFoundation.Python.3.11_qbz5n2kfra8p0\LocalCache\local-packages\Python311\site-packages\seaborn\_base.py", line 634, in __init__
    self.assign_variables(data, variables)
  File "C:\Users\24dan\AppData\Local\Packages\PythonSoftwareFoundation.Python.3.11_qbz5n2kfra8p0\LocalCache\local-packages\Python311\site-packages\seaborn\_base.py", line 679, in assign_variables
    plot_data = PlotData(data, variables)
                ^^^^^^^^^^^^^^^^^^^^^^^^^
  File "C:\Users\24dan\AppData\Local\Packages\PythonSoftwareFoundation.Python.3.11_qbz5n2kfra8p0\LocalCache\local-packages\Python311\site-packages\seaborn\_core\data.py", line 58, in __init__
    frame, names, ids = self._assign_variables(data, variables)
                        ^^^^^^^^^^^^^^^^^^^^^^^^^^^^^^^^^^^^^^^
  File "C:\Users\24dan\AppData\Local\Packages\PythonSoftwareFoundation.Python.3.11_qbz5n2kfra8p0\LocalCache\local-packages\Python311\site-packages\seaborn\_core\data.py", line 232, in _assign_variables
    raise ValueError(err)
ValueError: Could not interpret value `Month` for `x`. An entry with this name does not appear in `data`.

During handling of the above exception, another exception occurred:

Traceback (most recent call last):
  File "C:\Users\24dan\Documents\AccountingCapstone\DFA\src\main\python\scripts\generate_graphs.py", line 233, in <module>
    make_double_line(getDataFrame(str(sql_statement)), str(graph_name), 7, 14, graph_x_name, graph_y_name, graph_y2_name)
  File "C:\Users\24dan\Documents\AccountingCapstone\DFA\src\main\python\scripts\generate_graphs.py", line 176, in make_double_line
    raise RuntimeError("An error occurred while making double line graph: %s" % e)
RuntimeError: An error occurred while making double line graph: Could not interpret value `Month` for `x`. An entry with this name does not appear in `data`.
2024-04-15 10:10:18,059 - ERROR - An error occurred: An error occurred while making double line graph: Could not interpret value `Month` for `x`. An entry with this name does not appear in `data`.
Traceback (most recent call last):
  File "C:\Users\24dan\Documents\AccountingCapstone\DFA\src\main\python\scripts\generate_graphs.py", line 168, in make_double_line
    sns.lineplot(x=x_name, y=y_name, data=df, label=y_name)
  File "C:\Users\24dan\AppData\Local\Packages\PythonSoftwareFoundation.Python.3.11_qbz5n2kfra8p0\LocalCache\local-packages\Python311\site-packages\seaborn\relational.py", line 485, in lineplot
    p = _LinePlotter(
        ^^^^^^^^^^^^^
  File "C:\Users\24dan\AppData\Local\Packages\PythonSoftwareFoundation.Python.3.11_qbz5n2kfra8p0\LocalCache\local-packages\Python311\site-packages\seaborn\relational.py", line 216, in __init__
    super().__init__(data=data, variables=variables)
  File "C:\Users\24dan\AppData\Local\Packages\PythonSoftwareFoundation.Python.3.11_qbz5n2kfra8p0\LocalCache\local-packages\Python311\site-packages\seaborn\_base.py", line 634, in __init__
    self.assign_variables(data, variables)
  File "C:\Users\24dan\AppData\Local\Packages\PythonSoftwareFoundation.Python.3.11_qbz5n2kfra8p0\LocalCache\local-packages\Python311\site-packages\seaborn\_base.py", line 679, in assign_variables
    plot_data = PlotData(data, variables)
                ^^^^^^^^^^^^^^^^^^^^^^^^^
  File "C:\Users\24dan\AppData\Local\Packages\PythonSoftwareFoundation.Python.3.11_qbz5n2kfra8p0\LocalCache\local-packages\Python311\site-packages\seaborn\_core\data.py", line 58, in __init__
    frame, names, ids = self._assign_variables(data, variables)
                        ^^^^^^^^^^^^^^^^^^^^^^^^^^^^^^^^^^^^^^^
  File "C:\Users\24dan\AppData\Local\Packages\PythonSoftwareFoundation.Python.3.11_qbz5n2kfra8p0\LocalCache\local-packages\Python311\site-packages\seaborn\_core\data.py", line 232, in _assign_variables
    raise ValueError(err)
ValueError: Could not interpret value `Month` for `x`. An entry with this name does not appear in `data`.

During handling of the above exception, another exception occurred:

Traceback (most recent call last):
  File "C:\Users\24dan\Documents\AccountingCapstone\DFA\src\main\python\scripts\generate_graphs.py", line 233, in <module>
    make_double_line(getDataFrame(str(sql_statement)), str(graph_name), 7, 14, graph_x_name, graph_y_name, graph_y2_name)
  File "C:\Users\24dan\Documents\AccountingCapstone\DFA\src\main\python\scripts\generate_graphs.py", line 176, in make_double_line
    raise RuntimeError("An error occurred while making double line graph: %s" % e)
RuntimeError: An error occurred while making double line graph: Could not interpret value `Month` for `x`. An entry with this name does not appear in `data`.
2024-04-15 10:10:25,827 - ERROR - An error occurred: An error occurred while making double line graph: Could not interpret value `Month` for `x`. An entry with this name does not appear in `data`.
Traceback (most recent call last):
  File "C:\Users\24dan\Documents\AccountingCapstone\DFA\src\main\python\scripts\generate_graphs.py", line 168, in make_double_line
    sns.lineplot(x=x_name, y=y_name, data=df, label=y_name)
  File "C:\Users\24dan\AppData\Local\Packages\PythonSoftwareFoundation.Python.3.11_qbz5n2kfra8p0\LocalCache\local-packages\Python311\site-packages\seaborn\relational.py", line 485, in lineplot
    p = _LinePlotter(
        ^^^^^^^^^^^^^
  File "C:\Users\24dan\AppData\Local\Packages\PythonSoftwareFoundation.Python.3.11_qbz5n2kfra8p0\LocalCache\local-packages\Python311\site-packages\seaborn\relational.py", line 216, in __init__
    super().__init__(data=data, variables=variables)
  File "C:\Users\24dan\AppData\Local\Packages\PythonSoftwareFoundation.Python.3.11_qbz5n2kfra8p0\LocalCache\local-packages\Python311\site-packages\seaborn\_base.py", line 634, in __init__
    self.assign_variables(data, variables)
  File "C:\Users\24dan\AppData\Local\Packages\PythonSoftwareFoundation.Python.3.11_qbz5n2kfra8p0\LocalCache\local-packages\Python311\site-packages\seaborn\_base.py", line 679, in assign_variables
    plot_data = PlotData(data, variables)
                ^^^^^^^^^^^^^^^^^^^^^^^^^
  File "C:\Users\24dan\AppData\Local\Packages\PythonSoftwareFoundation.Python.3.11_qbz5n2kfra8p0\LocalCache\local-packages\Python311\site-packages\seaborn\_core\data.py", line 58, in __init__
    frame, names, ids = self._assign_variables(data, variables)
                        ^^^^^^^^^^^^^^^^^^^^^^^^^^^^^^^^^^^^^^^
  File "C:\Users\24dan\AppData\Local\Packages\PythonSoftwareFoundation.Python.3.11_qbz5n2kfra8p0\LocalCache\local-packages\Python311\site-packages\seaborn\_core\data.py", line 232, in _assign_variables
    raise ValueError(err)
ValueError: Could not interpret value `Month` for `x`. An entry with this name does not appear in `data`.

During handling of the above exception, another exception occurred:

Traceback (most recent call last):
  File "C:\Users\24dan\Documents\AccountingCapstone\DFA\src\main\python\scripts\generate_graphs.py", line 233, in <module>
    make_double_line(getDataFrame(str(sql_statement)), str(graph_name), 7, 14, graph_x_name, graph_y_name, graph_y2_name)
  File "C:\Users\24dan\Documents\AccountingCapstone\DFA\src\main\python\scripts\generate_graphs.py", line 176, in make_double_line
    raise RuntimeError("An error occurred while making double line graph: %s" % e)
RuntimeError: An error occurred while making double line graph: Could not interpret value `Month` for `x`. An entry with this name does not appear in `data`.
2024-04-15 10:11:07,059 - ERROR - An error occurred: An error occurred while making double line graph: Could not interpret value `Month` for `x`. An entry with this name does not appear in `data`.
Traceback (most recent call last):
  File "C:\Users\24dan\Documents\AccountingCapstone\DFA\src\main\python\scripts\generate_graphs.py", line 168, in make_double_line
    sns.lineplot(x=x_name, y=y_name, data=df, label=y_name)
  File "C:\Users\24dan\AppData\Local\Packages\PythonSoftwareFoundation.Python.3.11_qbz5n2kfra8p0\LocalCache\local-packages\Python311\site-packages\seaborn\relational.py", line 485, in lineplot
    p = _LinePlotter(
        ^^^^^^^^^^^^^
  File "C:\Users\24dan\AppData\Local\Packages\PythonSoftwareFoundation.Python.3.11_qbz5n2kfra8p0\LocalCache\local-packages\Python311\site-packages\seaborn\relational.py", line 216, in __init__
    super().__init__(data=data, variables=variables)
  File "C:\Users\24dan\AppData\Local\Packages\PythonSoftwareFoundation.Python.3.11_qbz5n2kfra8p0\LocalCache\local-packages\Python311\site-packages\seaborn\_base.py", line 634, in __init__
    self.assign_variables(data, variables)
  File "C:\Users\24dan\AppData\Local\Packages\PythonSoftwareFoundation.Python.3.11_qbz5n2kfra8p0\LocalCache\local-packages\Python311\site-packages\seaborn\_base.py", line 679, in assign_variables
    plot_data = PlotData(data, variables)
                ^^^^^^^^^^^^^^^^^^^^^^^^^
  File "C:\Users\24dan\AppData\Local\Packages\PythonSoftwareFoundation.Python.3.11_qbz5n2kfra8p0\LocalCache\local-packages\Python311\site-packages\seaborn\_core\data.py", line 58, in __init__
    frame, names, ids = self._assign_variables(data, variables)
                        ^^^^^^^^^^^^^^^^^^^^^^^^^^^^^^^^^^^^^^^
  File "C:\Users\24dan\AppData\Local\Packages\PythonSoftwareFoundation.Python.3.11_qbz5n2kfra8p0\LocalCache\local-packages\Python311\site-packages\seaborn\_core\data.py", line 232, in _assign_variables
    raise ValueError(err)
ValueError: Could not interpret value `Month` for `x`. An entry with this name does not appear in `data`.

During handling of the above exception, another exception occurred:

Traceback (most recent call last):
  File "C:\Users\24dan\Documents\AccountingCapstone\DFA\src\main\python\scripts\generate_graphs.py", line 233, in <module>
    make_double_line(getDataFrame(str(sql_statement)), str(graph_name), 7, 14, graph_x_name, graph_y_name, graph_y2_name)
  File "C:\Users\24dan\Documents\AccountingCapstone\DFA\src\main\python\scripts\generate_graphs.py", line 176, in make_double_line
    raise RuntimeError("An error occurred while making double line graph: %s" % e)
RuntimeError: An error occurred while making double line graph: Could not interpret value `Month` for `x`. An entry with this name does not appear in `data`.
2024-04-15 10:11:15,179 - ERROR - An error occurred: An error occurred while making double line graph: Could not interpret value `Month` for `x`. An entry with this name does not appear in `data`.
Traceback (most recent call last):
  File "C:\Users\24dan\Documents\AccountingCapstone\DFA\src\main\python\scripts\generate_graphs.py", line 168, in make_double_line
    sns.lineplot(x=x_name, y=y_name, data=df, label=y_name)
  File "C:\Users\24dan\AppData\Local\Packages\PythonSoftwareFoundation.Python.3.11_qbz5n2kfra8p0\LocalCache\local-packages\Python311\site-packages\seaborn\relational.py", line 485, in lineplot
    p = _LinePlotter(
        ^^^^^^^^^^^^^
  File "C:\Users\24dan\AppData\Local\Packages\PythonSoftwareFoundation.Python.3.11_qbz5n2kfra8p0\LocalCache\local-packages\Python311\site-packages\seaborn\relational.py", line 216, in __init__
    super().__init__(data=data, variables=variables)
  File "C:\Users\24dan\AppData\Local\Packages\PythonSoftwareFoundation.Python.3.11_qbz5n2kfra8p0\LocalCache\local-packages\Python311\site-packages\seaborn\_base.py", line 634, in __init__
    self.assign_variables(data, variables)
  File "C:\Users\24dan\AppData\Local\Packages\PythonSoftwareFoundation.Python.3.11_qbz5n2kfra8p0\LocalCache\local-packages\Python311\site-packages\seaborn\_base.py", line 679, in assign_variables
    plot_data = PlotData(data, variables)
                ^^^^^^^^^^^^^^^^^^^^^^^^^
  File "C:\Users\24dan\AppData\Local\Packages\PythonSoftwareFoundation.Python.3.11_qbz5n2kfra8p0\LocalCache\local-packages\Python311\site-packages\seaborn\_core\data.py", line 58, in __init__
    frame, names, ids = self._assign_variables(data, variables)
                        ^^^^^^^^^^^^^^^^^^^^^^^^^^^^^^^^^^^^^^^
  File "C:\Users\24dan\AppData\Local\Packages\PythonSoftwareFoundation.Python.3.11_qbz5n2kfra8p0\LocalCache\local-packages\Python311\site-packages\seaborn\_core\data.py", line 232, in _assign_variables
    raise ValueError(err)
ValueError: Could not interpret value `Month` for `x`. An entry with this name does not appear in `data`.

During handling of the above exception, another exception occurred:

Traceback (most recent call last):
  File "C:\Users\24dan\Documents\AccountingCapstone\DFA\src\main\python\scripts\generate_graphs.py", line 233, in <module>
    make_double_line(getDataFrame(str(sql_statement)), str(graph_name), 7, 14, graph_x_name, graph_y_name, graph_y2_name)
  File "C:\Users\24dan\Documents\AccountingCapstone\DFA\src\main\python\scripts\generate_graphs.py", line 176, in make_double_line
    raise RuntimeError("An error occurred while making double line graph: %s" % e)
RuntimeError: An error occurred while making double line graph: Could not interpret value `Month` for `x`. An entry with this name does not appear in `data`.
2024-04-15 10:14:54,487 - ERROR - An error occurred: An error occurred while making double line graph: Could not interpret value `Month` for `x`. An entry with this name does not appear in `data`.
Traceback (most recent call last):
  File "C:\Users\24dan\Documents\AccountingCapstone\DFA\src\main\python\scripts\generate_graphs.py", line 168, in make_double_line
    sns.lineplot(x=x_name, y=y_name, data=df, label=y_name)
  File "C:\Users\24dan\AppData\Local\Packages\PythonSoftwareFoundation.Python.3.11_qbz5n2kfra8p0\LocalCache\local-packages\Python311\site-packages\seaborn\relational.py", line 485, in lineplot
    p = _LinePlotter(
        ^^^^^^^^^^^^^
  File "C:\Users\24dan\AppData\Local\Packages\PythonSoftwareFoundation.Python.3.11_qbz5n2kfra8p0\LocalCache\local-packages\Python311\site-packages\seaborn\relational.py", line 216, in __init__
    super().__init__(data=data, variables=variables)
  File "C:\Users\24dan\AppData\Local\Packages\PythonSoftwareFoundation.Python.3.11_qbz5n2kfra8p0\LocalCache\local-packages\Python311\site-packages\seaborn\_base.py", line 634, in __init__
    self.assign_variables(data, variables)
  File "C:\Users\24dan\AppData\Local\Packages\PythonSoftwareFoundation.Python.3.11_qbz5n2kfra8p0\LocalCache\local-packages\Python311\site-packages\seaborn\_base.py", line 679, in assign_variables
    plot_data = PlotData(data, variables)
                ^^^^^^^^^^^^^^^^^^^^^^^^^
  File "C:\Users\24dan\AppData\Local\Packages\PythonSoftwareFoundation.Python.3.11_qbz5n2kfra8p0\LocalCache\local-packages\Python311\site-packages\seaborn\_core\data.py", line 58, in __init__
    frame, names, ids = self._assign_variables(data, variables)
                        ^^^^^^^^^^^^^^^^^^^^^^^^^^^^^^^^^^^^^^^
  File "C:\Users\24dan\AppData\Local\Packages\PythonSoftwareFoundation.Python.3.11_qbz5n2kfra8p0\LocalCache\local-packages\Python311\site-packages\seaborn\_core\data.py", line 232, in _assign_variables
    raise ValueError(err)
ValueError: Could not interpret value `Month` for `x`. An entry with this name does not appear in `data`.

During handling of the above exception, another exception occurred:

Traceback (most recent call last):
  File "C:\Users\24dan\Documents\AccountingCapstone\DFA\src\main\python\scripts\generate_graphs.py", line 233, in <module>
    make_double_line(getDataFrame(str(sql_statement)), str(graph_name), 7, 14, graph_x_name, graph_y_name, graph_y2_name)
  File "C:\Users\24dan\Documents\AccountingCapstone\DFA\src\main\python\scripts\generate_graphs.py", line 176, in make_double_line
    raise RuntimeError("An error occurred while making double line graph: %s" % e)
RuntimeError: An error occurred while making double line graph: Could not interpret value `Month` for `x`. An entry with this name does not appear in `data`.
2024-04-15 10:15:06,303 - ERROR - An error occurred: An error occurred while making double line graph: Could not interpret value `Month` for `x`. An entry with this name does not appear in `data`.
Traceback (most recent call last):
  File "C:\Users\24dan\Documents\AccountingCapstone\DFA\src\main\python\scripts\generate_graphs.py", line 168, in make_double_line
    sns.lineplot(x=x_name, y=y_name, data=df, label=y_name)
  File "C:\Users\24dan\AppData\Local\Packages\PythonSoftwareFoundation.Python.3.11_qbz5n2kfra8p0\LocalCache\local-packages\Python311\site-packages\seaborn\relational.py", line 485, in lineplot
    p = _LinePlotter(
        ^^^^^^^^^^^^^
  File "C:\Users\24dan\AppData\Local\Packages\PythonSoftwareFoundation.Python.3.11_qbz5n2kfra8p0\LocalCache\local-packages\Python311\site-packages\seaborn\relational.py", line 216, in __init__
    super().__init__(data=data, variables=variables)
  File "C:\Users\24dan\AppData\Local\Packages\PythonSoftwareFoundation.Python.3.11_qbz5n2kfra8p0\LocalCache\local-packages\Python311\site-packages\seaborn\_base.py", line 634, in __init__
    self.assign_variables(data, variables)
  File "C:\Users\24dan\AppData\Local\Packages\PythonSoftwareFoundation.Python.3.11_qbz5n2kfra8p0\LocalCache\local-packages\Python311\site-packages\seaborn\_base.py", line 679, in assign_variables
    plot_data = PlotData(data, variables)
                ^^^^^^^^^^^^^^^^^^^^^^^^^
  File "C:\Users\24dan\AppData\Local\Packages\PythonSoftwareFoundation.Python.3.11_qbz5n2kfra8p0\LocalCache\local-packages\Python311\site-packages\seaborn\_core\data.py", line 58, in __init__
    frame, names, ids = self._assign_variables(data, variables)
                        ^^^^^^^^^^^^^^^^^^^^^^^^^^^^^^^^^^^^^^^
  File "C:\Users\24dan\AppData\Local\Packages\PythonSoftwareFoundation.Python.3.11_qbz5n2kfra8p0\LocalCache\local-packages\Python311\site-packages\seaborn\_core\data.py", line 232, in _assign_variables
    raise ValueError(err)
ValueError: Could not interpret value `Month` for `x`. An entry with this name does not appear in `data`.

During handling of the above exception, another exception occurred:

Traceback (most recent call last):
  File "C:\Users\24dan\Documents\AccountingCapstone\DFA\src\main\python\scripts\generate_graphs.py", line 233, in <module>
    make_double_line(getDataFrame(str(sql_statement)), str(graph_name), 7, 14, graph_x_name, graph_y_name, graph_y2_name)
  File "C:\Users\24dan\Documents\AccountingCapstone\DFA\src\main\python\scripts\generate_graphs.py", line 176, in make_double_line
    raise RuntimeError("An error occurred while making double line graph: %s" % e)
RuntimeError: An error occurred while making double line graph: Could not interpret value `Month` for `x`. An entry with this name does not appear in `data`.
2024-04-15 10:15:13,206 - ERROR - An error occurred: An error occurred while making double line graph: Could not interpret value `Month` for `x`. An entry with this name does not appear in `data`.
Traceback (most recent call last):
  File "C:\Users\24dan\Documents\AccountingCapstone\DFA\src\main\python\scripts\generate_graphs.py", line 168, in make_double_line
    sns.lineplot(x=x_name, y=y_name, data=df, label=y_name)
  File "C:\Users\24dan\AppData\Local\Packages\PythonSoftwareFoundation.Python.3.11_qbz5n2kfra8p0\LocalCache\local-packages\Python311\site-packages\seaborn\relational.py", line 485, in lineplot
    p = _LinePlotter(
        ^^^^^^^^^^^^^
  File "C:\Users\24dan\AppData\Local\Packages\PythonSoftwareFoundation.Python.3.11_qbz5n2kfra8p0\LocalCache\local-packages\Python311\site-packages\seaborn\relational.py", line 216, in __init__
    super().__init__(data=data, variables=variables)
  File "C:\Users\24dan\AppData\Local\Packages\PythonSoftwareFoundation.Python.3.11_qbz5n2kfra8p0\LocalCache\local-packages\Python311\site-packages\seaborn\_base.py", line 634, in __init__
    self.assign_variables(data, variables)
  File "C:\Users\24dan\AppData\Local\Packages\PythonSoftwareFoundation.Python.3.11_qbz5n2kfra8p0\LocalCache\local-packages\Python311\site-packages\seaborn\_base.py", line 679, in assign_variables
    plot_data = PlotData(data, variables)
                ^^^^^^^^^^^^^^^^^^^^^^^^^
  File "C:\Users\24dan\AppData\Local\Packages\PythonSoftwareFoundation.Python.3.11_qbz5n2kfra8p0\LocalCache\local-packages\Python311\site-packages\seaborn\_core\data.py", line 58, in __init__
    frame, names, ids = self._assign_variables(data, variables)
                        ^^^^^^^^^^^^^^^^^^^^^^^^^^^^^^^^^^^^^^^
  File "C:\Users\24dan\AppData\Local\Packages\PythonSoftwareFoundation.Python.3.11_qbz5n2kfra8p0\LocalCache\local-packages\Python311\site-packages\seaborn\_core\data.py", line 232, in _assign_variables
    raise ValueError(err)
ValueError: Could not interpret value `Month` for `x`. An entry with this name does not appear in `data`.

During handling of the above exception, another exception occurred:

Traceback (most recent call last):
  File "C:\Users\24dan\Documents\AccountingCapstone\DFA\src\main\python\scripts\generate_graphs.py", line 233, in <module>
    make_double_line(getDataFrame(str(sql_statement)), str(graph_name), 7, 14, graph_x_name, graph_y_name, graph_y2_name)
  File "C:\Users\24dan\Documents\AccountingCapstone\DFA\src\main\python\scripts\generate_graphs.py", line 176, in make_double_line
    raise RuntimeError("An error occurred while making double line graph: %s" % e)
RuntimeError: An error occurred while making double line graph: Could not interpret value `Month` for `x`. An entry with this name does not appear in `data`.
