2024-04-04 09:55:58,685 - ERROR - An error occurred: ('IM002', '[IM002] [Microsoft][ODBC Driver Manager] Data source name not found and no default driver specified')
Traceback (most recent call last):
  File "C:\Users\24dan\Documents\AccountingCapstone\DFA\src\main\python\scripts\generate_graphs.py", line 114, in <module>
    make_pie_chart(getDataFrame(str(sql_statement)), str(graph_name), 10, 10, graph_x_name)
                   ^^^^^^^^^^^^^^^^^^^^^^^^^^^^^^^^
  File "C:\Users\24dan\Documents\AccountingCapstone\DFA\src\main\python\scripts\generate_graphs.py", line 30, in getDataFrame
    conn = odbc.connect(connection_string)
           ^^^^^^^^^^^^^^^^^^^^^^^^^^^^^^^
  File "C:\Users\24dan\AppData\Local\Packages\PythonSoftwareFoundation.Python.3.11_qbz5n2kfra8p0\LocalCache\local-packages\Python311\site-packages\pypyodbc.py", line 2454, in __init__
    self.connect(connectString, autocommit, ansi, timeout, unicode_results, readonly)
  File "C:\Users\24dan\AppData\Local\Packages\PythonSoftwareFoundation.Python.3.11_qbz5n2kfra8p0\LocalCache\local-packages\Python311\site-packages\pypyodbc.py", line 2507, in connect
    check_success(self, ret)
  File "C:\Users\24dan\AppData\Local\Packages\PythonSoftwareFoundation.Python.3.11_qbz5n2kfra8p0\LocalCache\local-packages\Python311\site-packages\pypyodbc.py", line 1009, in check_success
    ctrl_err(SQL_HANDLE_DBC, ODBC_obj.dbc_h, ret, ODBC_obj.ansi)
  File "C:\Users\24dan\AppData\Local\Packages\PythonSoftwareFoundation.Python.3.11_qbz5n2kfra8p0\LocalCache\local-packages\Python311\site-packages\pypyodbc.py", line 985, in ctrl_err
    raise Error(state,err_text)
pypyodbc.Error: ('IM002', '[IM002] [Microsoft][ODBC Driver Manager] Data source name not found and no default driver specified')
2024-04-04 09:55:59,320 - ERROR - An error occurred: ('IM002', '[IM002] [Microsoft][ODBC Driver Manager] Data source name not found and no default driver specified')
Traceback (most recent call last):
  File "C:\Users\24dan\Documents\AccountingCapstone\DFA\src\main\python\scripts\generate_graphs.py", line 114, in <module>
    make_pie_chart(getDataFrame(str(sql_statement)), str(graph_name), 10, 10, graph_x_name)
                   ^^^^^^^^^^^^^^^^^^^^^^^^^^^^^^^^
  File "C:\Users\24dan\Documents\AccountingCapstone\DFA\src\main\python\scripts\generate_graphs.py", line 30, in getDataFrame
    conn = odbc.connect(connection_string)
           ^^^^^^^^^^^^^^^^^^^^^^^^^^^^^^^
  File "C:\Users\24dan\AppData\Local\Packages\PythonSoftwareFoundation.Python.3.11_qbz5n2kfra8p0\LocalCache\local-packages\Python311\site-packages\pypyodbc.py", line 2454, in __init__
    self.connect(connectString, autocommit, ansi, timeout, unicode_results, readonly)
  File "C:\Users\24dan\AppData\Local\Packages\PythonSoftwareFoundation.Python.3.11_qbz5n2kfra8p0\LocalCache\local-packages\Python311\site-packages\pypyodbc.py", line 2507, in connect
    check_success(self, ret)
  File "C:\Users\24dan\AppData\Local\Packages\PythonSoftwareFoundation.Python.3.11_qbz5n2kfra8p0\LocalCache\local-packages\Python311\site-packages\pypyodbc.py", line 1009, in check_success
    ctrl_err(SQL_HANDLE_DBC, ODBC_obj.dbc_h, ret, ODBC_obj.ansi)
  File "C:\Users\24dan\AppData\Local\Packages\PythonSoftwareFoundation.Python.3.11_qbz5n2kfra8p0\LocalCache\local-packages\Python311\site-packages\pypyodbc.py", line 985, in ctrl_err
    raise Error(state,err_text)
pypyodbc.Error: ('IM002', '[IM002] [Microsoft][ODBC Driver Manager] Data source name not found and no default driver specified')
